Workbook

Sheet 2024 -2025-2026
A1: S.No | B1: Authors | C1: Title | D1: Source title | E1: Volume | F1: Issue | G1: Year | H1: DOI | I1: Link | J1: Document Type in Scopus | K1: Document Type as per Report | L1: Department | M1: Name of the Faculty
A2: 1 | B2: Bruntha P.M.; Neebha T.M.; Dhanasekar S.; Pandian S.I.A.; Abraham S.S.; Kumar S.N.; Anitha J. | C2: Lung Nodule Classification using Shallow CNNs and Deep Transfer Learning CNNs | D2: 2021 7th International Conference on Advanced Computing and Communication Systems, ICACCS 2021 | G2: 2021 | H2: 10.1109/ICACCS51430.2021.9441702 | I2: https://www.scopus.com/inward/record.uri?eid=2-s2.0-85108026954&doi=10.1109%2fICACCS51430.2021.9441702&partnerID=40&md5=128e9b7d1c33e42b3181084abffa12ba | J2: Conference paper | K2: Scopus/WoS Conference/Book Chapter/Others | L2: ECE
A3: 2 | B3: Roberts M.K.; Anguraj P. | C3: A Comparative Review of Recent Advances in Decoding Algorithms for Low-Density Parity-Check (LDPC) Codes and Their Applications | D3: Archives of Computational Methods in Engineering | E3: 28 | G3: 2021 | H3: 10.1007/s11831-020-09466-6 | I3: https://www.scopus.com/inward/record.uri?eid=2-s2.0-85088038531&doi=10.1007%2fs11831-020-09466-6&partnerID=40&md5=59ea8e42f6b608cd24a9689459baaa0b | J3: Article | K3: SCI | L3: ECE
A4: 3 | B4: Saravanan M.; Parthasarathy E. | C4: Investigation of RF/Analog Performance of InAs/InGaAs Channel Based Nanowire TFETS | D4: ICCISc 2021 - 2021 International Conference on Communication, Control and Information Sciences, Proceedings | G4: 2021 | H4: 10.1109/ICCISc52257.2021.9484973 | I4: https://www.scopus.com/inward/record.uri?eid=2-s2.0-85113304126&doi=10.1109%2fICCISc52257.2021.9484973&partnerID=40&md5=bbfe557847a5faff57b86f87a849efa6 | J4: Conference paper | K4: Scopus/WoS Conference/Book Chapter/Others | L4: CSE
A5: 4 | B5: Murugan S.; Anandakumar H. | C5: Privacy Information Leakage Prevention in Cognitive Social Mining Applications: Causes and Prevention Measures | D5: Research Anthology on Privatizing and Securing Data | G5: 2021 | H5: 10.4018/978-1-7998-8954-0.ch103 | I5: https://www.scopus.com/inward/record.uri?eid=2-s2.0-85134940087&doi=10.4018%2f978-1-7998-8954-0.ch103&partnerID=40&md5=f7afe281062e02dfb2497391ae8e0022 | J5: Book chapter | K5: Scopus/WoS Conference/Book Chapter/Others | L5: CSE
A6: 5 | B6: Yang C.-Y.; Sharif M.; Ravana S.D.; Haldorai A. | C6: Big Cloud Innovation for Sustainable Wireless Management | D6: Wireless Personal Communications | E6: 117 | G6: 2021 | H6: 10.1007/s11277-021-08250-4 | I6: https://www.scopus.com/inward/record.uri?eid=2-s2.0-85101047207&doi=10.1007%2fs11277-021-08250-4&partnerID=40&md5=8bf5ba1d0c35a10db8cbde3298fab2d8 | J6: Editorial | K6: Scopus/WoS Conference/Book Chapter/Others | L6: CSE
A7: 6 | B7: Roberts M.K.; Anguraj P.; Krishnan T. | C7: Design and Analysis of Improved Low Power and High-Speed N-Bit Adder | D7: 2021 International Conference on Decision Aid Sciences and Application, DASA 2021 | G7: 2021 | H7: 10.1109/DASA53625.2021.9682405 | I7: https://www.scopus.com/inward/record.uri?eid=2-s2.0-85125797289&doi=10.1109%2fDASA53625.2021.9682405&partnerID=40&md5=dfad45ec5053baecd9a47bfdc2c72c74 | J7: Conference paper | K7: Scopus/WoS Conference/Book Chapter/Others | L7: ECE
A8: 7 | B8: Gnanasekaran S.; Chelladurai S.J.S.; Ramakrishnan T.; Sivananthan S.; Padmanaban G.; Arthanari R.; Balasubramanian V. | C8: Optimizing the characteristics of the laser hardfacing process parameters to maximize the wear resistance of Ni-based hard-faced deposits using the RSM technique | D8: Advances in Materials Science and Engineering | E8: 2021 | G8: 2021 | H8: 10.1155/2021/3665631 | I8: https://www.scopus.com/inward/record.uri?eid=2-s2.0-85123056746&doi=10.1155%2f2021%2f3665631&partnerID=40&md5=3876872d08653fa7744d0087e4159ab9 | J8: Retracted | K8: Scopus/WoS Journals | L8: Mech
A9: 8 | B9: Suresh Kumar R.; Senthil Kumar S.; Murugan K.; Hailegiorgis S.M. | C9: Green Machining Characteristics Study of Al-6063 in CNC Milling Using Taguchi Method and Grey Relational Analysis | D9: Advances in Materials Science and Engineering | E9: 2021 | G9: 2021 | H9: 10.1155/2021/4420250 | I9: https://www.scopus.com/inward/record.uri?eid=2-s2.0-85122407842&doi=10.1155%2f2021%2f4420250&partnerID=40&md5=965b77f400f02a00d94ed5d686f0093a | J9: Retracted | K9: Scopus/WoS Journals | L9: Mech
A10: 9 | B10: UMADEVI M.; RATHINAM R.; POORNIMA S.; SANTHI T.; PATTABHI S. | C10: Electrochemical degradation of reactive red 195 from its aqueous solution using ruo2/iro2/tao2 coated titanium electrodes | D10: Asian Journal of Chemistry | E10: 33 | G10: 2021 | H10: 10.14233/ajchem.2021.23330 | I10: https://www.scopus.com/inward/record.uri?eid=2-s2.0-85111191361&doi=10.14233%2fajchem.2021.23330&partnerID=40&md5=0ab257b70b055ac5c152a9c58b7ab0ea | J10: Article | K10: SCI | L10: S&H
A11: 10 | B11: Pradeep R.; Myilsamy K.; Vijaykumar V.R.; Kumar A.S. | C11: An optimized SIR Modeling for Analyzing the Spreading Rate of Covid-19 Pandemic | D11: 2021 7th International Conference on Advanced Computing and Communication Systems, ICACCS 2021 | G11: 2021 | H11: 10.1109/ICACCS51430.2021.9441791 | I11: https://www.scopus.com/inward/record.uri?eid=2-s2.0-85108027811&doi=10.1109%2fICACCS51430.2021.9441791&partnerID=40&md5=f21430870648a3292b1f57493c117b1b | J11: Conference paper | K11: Scopus/WoS Conference/Book Chapter/Others | L11: ECE
A12: 11 | B12: Nisar K.S.; Jothimani K.; Kaliraj K.; Ravichandran C. | C12: An analysis of controllability results for nonlinear Hilfer neutral fractional derivatives with non-dense domain | D12: Chaos, Solitons and Fractals | E12: 146 | G12: 2021 | H12: 10.1016/j.chaos.2021.110915 | I12: https://www.scopus.com/inward/record.uri?eid=2-s2.0-85103787277&doi=10.1016%2fj.chaos.2021.110915&partnerID=40&md5=1e67594cece01cf64b972ea9f1fbcf53 | J12: Article | K12: Scopus/WoS Journals | L12: S&H
A13: 12 | B13: Mayurappriyan P.S.; Loganathan N.; Shanmugapriya M.; Anbarasu P.; Sakthi P.K.A. | C13: Evolution of Outcome Based Engineering Education in India - A Case Study | D13: 2021 7th International Conference on Advanced Computing and Communication Systems, ICACCS 2021 | G13: 2021 | H13: 10.1109/ICACCS51430.2021.9441676 | I13: https://www.scopus.com/inward/record.uri?eid=2-s2.0-85108028501&doi=10.1109%2fICACCS51430.2021.9441676&partnerID=40&md5=6113f61623d1007dac06e2dee4953d2e | J13: Conference paper | K13: Scopus/WoS Conference/Book Chapter/Others | L13: EEE
A14: 13 | B14: Suresh Kumar R.; Senthil Kumar S.; Murugan K.; Guruprasad B.; Manavalla S.; Madhu S.; Hariprabhu M.; Balamuralitharan S.; Venkatesa Prabhu S. | C14: Optimization of CNC End Milling Process Parameters of Low-Carbon Mold Steel Using Response Surface Methodology and Grey Relational Analysis | D14: Advances in Materials Science and Engineering | E14: 2021 | G14: 2021 | H14: 10.1155/2021/4005728 | I14: https://www.scopus.com/inward/record.uri?eid=2-s2.0-85114091035&doi=10.1155%2f2021%2f4005728&partnerID=40&md5=0de58ff56cb65189fd1843767e8a125f | J14: Retracted | K14: Scopus/WoS Journals | L14: Mech
A15: 14 | B15: Haldorai A.; Murugan S.; Ramu A. | C15: Evolution, challenges, and application of intelligent ICT education: An overview | D15: Computer Applications in Engineering Education | E15: 29 | G15: 2021 | H15: 10.1002/cae.22217 | I15: https://www.scopus.com/inward/record.uri?eid=2-s2.0-85081017759&doi=10.1002%2fcae.22217&partnerID=40&md5=cb112dd0f5559a3e89d62d537ef75b4f | J15: Article | K15: SCI | L15: CSE
A16: 15 | B16: Raja L.; Farithkhan A.; Vijayalakshmi K.; Sripriya T.; Krishnan R.; Devnesh K.N. | C16: Design of Cubic Dielectric Resonator Antenna for Biomedical Application | D16: Proceedings of the 2021 IEEE International Conference on Innovative Computing, Intelligent Communication and Smart Electrical Systems, ICSES 2021 | G16: 2021 | H16: 10.1109/ICSES52305.2021.9633792 | I16: https://www.scopus.com/inward/record.uri?eid=2-s2.0-85123806073&doi=10.1109%2fICSES52305.2021.9633792&partnerID=40&md5=027b25145050c1cae0262ad965f1403d | J16: Conference paper | K16: Scopus/WoS Conference/Book Chapter/Others | L16: ECE
A17: 16 | B17: Natarajan Phd B.; Subramanian B.; Kanagaraj K.; Soundararajan R. | C17: Experimental Study on SS 304 Sheet Metal for Bending Process Optimization using Response Surface Method | D17: SAE Technical Papers | E17: Part 173236 | G17: 2021 | H17: 10.4271/2021-28-0268 | I17: https://www.scopus.com/inward/record.uri?eid=2-s2.0-85118604573&doi=10.4271%2f2021-28-0268&partnerID=40&md5=6b0c2d915f9708d4612279c1220b67c0 | J17: Conference paper | K17: Scopus/WoS Conference/Book Chapter/Others | L17: MECH | M17: Ms. Hemalatha R
A18: 17 | B18: Satishkumar P.; Gokila Krishnan G.; Seenivasan S.; Rajarathnam P. | C18: A study on tribological evaluation of hybrid aluminium metal matrix for thermal application | D18: Materials Today: Proceedings | E18: 81 | G18: 2021 | H18: 10.1016/j.matpr.2021.04.389 | I18: https://www.scopus.com/inward/record.uri?eid=2-s2.0-85184719183&doi=10.1016%2fj.matpr.2021.04.389&partnerID=40&md5=6228a690885a95b9f726266c6ad69d13 | J18: Conference paper | K18: Scopus/WoS Conference/Book Chapter/Others | L18: Mech
A19: 18 | B19: Gupta A.K.; Maity T.; H A.; Chauhan Y.K. | C19: An electromagnetic strategy to improve the performance of PV panel under partial shading | D19: Computers and Electrical Engineering | E19: 90 | G19: 2021 | H19: 10.1016/j.compeleceng.2020.106896 | I19: https://www.scopus.com/inward/record.uri?eid=2-s2.0-85094914685&doi=10.1016%2fj.compeleceng.2020.106896&partnerID=40&md5=c86ac01e0edba782a23cf448efc48ae1 | J19: Article | K19: Scopus/WoS Journals | L19: CSE
A20: 19 | B20: Latha R.; Adharsh Babu S.; Vivek Kumar M. | C20: Design and Analysis of Multi-Device Interleaved Boost Converter Driving an Induction Motor | D20: IOP Conference Series: Earth and Environmental Science | E20: 850 | G20: 2021 | H20: 10.1088/1755-1315/850/1/012036 | I20: https://www.scopus.com/inward/record.uri?eid=2-s2.0-85120472296&doi=10.1088%2f1755-1315%2f850%2f1%2f012036&partnerID=40&md5=df1b41a01acafd202c3e625d827f2a33 | J20: Editorial | K20: Scopus/WoS Conference/Book Chapter/Others | L20: ECE
A21: 20 | B21: Sreemathy J.; Naveen Durai K.; Lakshmi Priya E.; Deebika R.; Suganthi K.; Aisshwarya P.T. | C21: Data Integration and ETL: A Theoretical Perspective | D21: 2021 7th International Conference on Advanced Computing and Communication Systems, ICACCS 2021 | G21: 2021 | H21: 10.1109/ICACCS51430.2021.9441997 | I21: https://www.scopus.com/inward/record.uri?eid=2-s2.0-85108022889&doi=10.1109%2fICACCS51430.2021.9441997&partnerID=40&md5=86750bcaf6437255d9b783f3dd74aeb9 | J21: Conference paper | K21: Scopus/WoS Conference/Book Chapter/Others | L21: CSE
A22: 21 | B22: Ramu A.; Chen M.-Y.; Ravana S.D.; Haldorai A. | C22: Signal processing techniques for sustainable cognitive radio communications | D22: Wireless Networks | E22: 27 | G22: 2021 | H22: 10.1007/s11276-020-02503-z | I22: https://www.scopus.com/inward/record.uri?eid=2-s2.0-85096215135&doi=10.1007%2fs11276-020-02503-z&partnerID=40&md5=039240eee283856c9aee62eb1449a773 | J22: Editorial | K22: Scopus/WoS Conference/Book Chapter/Others | L22: CSE
A23: 22 | B23: Gokila A.; Ayyappan S. | C23: Quantum chemical insight properties of glyphosine(N, N-Bis (phosphonomethyl) glycine) – a combined hf and density functional study | D23: Digest Journal of Nanomaterials and Biostructures | E23: 16 | G23: 2021 | H23: 10.15251/DJNB.2021.162.535 | I23: https://www.scopus.com/inward/record.uri?eid=2-s2.0-85148617107&doi=10.15251%2fDJNB.2021.162.535&partnerID=40&md5=e83bc51305aed888c9a2319080e9a880 | J23: Article | K23: Scopus/WoS Journals | L23: S&H
A24: 23 | B24: AnishFathima B.; Mahaboob M. | C24: Design and Analysis of Energy Efficient Domino Logic Architectures with Single Electron Transistors in Pull Down Network and Keeper Topology | D24: EAI Endorsed Transactions on Energy Web | E24: 8 | G24: 2021 | H24: 10.4108/eai.27-11-2020.167287 | I24: https://www.scopus.com/inward/record.uri?eid=2-s2.0-85106659431&doi=10.4108%2feai.27-11-2020.167287&partnerID=40&md5=ada3e79e117acff68735bc1c54e839ce | J24: Article | K24: Scopus/WoS Journals | L24: ECE
A25: 24 | B25: Ganesh R.S.; Anuradha B.; Karthikeyan S.; Vijayalakshmi P.; Ashok M.; Nagaraj V. | C25: Biometrics based Smart and Secured Electronic Voting Machine | D25: Proceedings - 2nd International Conference on Smart Electronics and Communication, ICOSEC 2021 | G25: 2021 | H25: 10.1109/ICOSEC51865.2021.9591865 | I25: https://www.scopus.com/inward/record.uri?eid=2-s2.0-85123174442&doi=10.1109%2fICOSEC51865.2021.9591865&partnerID=40&md5=3d32a9f94aba4a4e394d5f3f156f1d1a | J25: Conference paper | K25: Scopus/WoS Conference/Book Chapter/Others | L25: ECE
A26: 25 | B26: Thamaraimanalan T.; Mohankumar M.; Dhanasekaran S.; Anandakumar H. | C26: Experimental analysis of intelligent vehicle monitoring system using Internet of Things (IoT) | D26: EAI Endorsed Transactions on Energy Web | E26: 8 | G26: 2021 | H26: 10.4108/eai.16-4-2021.169336 | I26: https://www.scopus.com/inward/record.uri?eid=2-s2.0-85121215064&doi=10.4108%2feai.16-4-2021.169336&partnerID=40&md5=fb22578b3d5a2c697d075fc57a14d096 | J26: Article | K26: Scopus/WoS Journals | L26: CSE
A27: 26 | B27: Kowsalya M.; Elakya A.; Pradeep R. | C27: Solar Operated PLC Based Automated Irrigation System with Fault Preventer | D27: 2021 7th International Conference on Advanced Computing and Communication Systems, ICACCS 2021 | G27: 2021 | H27: 10.1109/ICACCS51430.2021.9441796 | I27: https://www.scopus.com/inward/record.uri?eid=2-s2.0-85108026296&doi=10.1109%2fICACCS51430.2021.9441796&partnerID=40&md5=9cd5e15dcde685735ba9b004d06f9fdf | J27: Conference paper | K27: Scopus/WoS Conference/Book Chapter/Others | L27: ECE
A28: 27 | B28: Jothimani K.; Kaliraj K.; Panda S.K.; Nisar K.S.; Raviohandran C. | C28: RESULTS ON CONTROLLABILITY OF NON-DENSELY CHARACTERIZED NEUTRAL FRACTIONAL DELAY DIFFERENTIAL SYSTEM | D28: Evolution Equations and Control Theory | E28: 10 | G28: 2021 | H28: 10.3934/eect.2020083 | I28: https://www.scopus.com/inward/record.uri?eid=2-s2.0-85096688930&doi=10.3934%2feect.2020083&partnerID=40&md5=fb00be2803ab5f3b63f57576777db55a | J28: Article | K28: Scopus/WoS Journals | L28: S&H
A29: 28 | B29: Rathinam R.; Brindha T.; Petchiammal M.; Ibrahim A.M. | C29: Photo-Electrocatalytic Degradation Of Aqueous Rhodamine B Dye Using Titanium Electrodes Coated With RuO2/lrO2/TaO2 | D29: Indian Journal of Environmental Protection | E29: 41 | G29: 2021 | I29: https://www.scopus.com/inward/record.uri?eid=2-s2.0-85126982129&partnerID=40&md5=8654577449f65af5eca05c63d4f4475e | J29: Article | K29: SCI | L29: S&H
A30: 29 | B30: Kingston Roberts M.; Kumari S.; Anguraj P. | C30: Certain investigations on recent advances in the design of decoding algorithms using low-density parity-check codes and its applications | D30: International Journal of Communication Systems | E30: 34 | G30: 2021 | H30: 10.1002/dac.4765 | I30: https://www.scopus.com/inward/record.uri?eid=2-s2.0-85103065887&doi=10.1002%2fdac.4765&partnerID=40&md5=4127316f06f6dfda196321e516fc7c38 | J30: Article | K30: SCI | L30: ECE
A31: 30 | B31: Sureshbabu Y.; Ashoka Varthanan P. | C31: Experimental investigation on four-stroke catalytic coated spark ignition engine to promote cleaner environment | D31: International Journal of Enterprise Network Management | E31: 12 | G31: 2021 | H31: 10.1504/IJENM.2021.116437 | I31: https://www.scopus.com/inward/record.uri?eid=2-s2.0-85111469571&doi=10.1504%2fIJENM.2021.116437&partnerID=40&md5=bad0f35b031b65e88fb8afb386b7410a | J31: Article | K31: Scopus/WoS Journals | L31: MECH
A32: 31 | B32: Alhomdy S.; Thabit F.; Abdulrazzak F.H.; Haldorai A.; Jagtap S. | C32: The role of cloud computing technology: A savior to fight the lockdown in COVID 19 crisis, the benefits, characteristics and applications | D32: International Journal of Intelligent Networks | E32: 2 | G32: 2021 | H32: 10.1016/j.ijin.2021.08.001 | I32: https://www.scopus.com/inward/record.uri?eid=2-s2.0-85129999273&doi=10.1016%2fj.ijin.2021.08.001&partnerID=40&md5=6931497baf6ccd4f4140d9c81eaba233 | J32: Article | K32: SCI | L32: CSE
A33: 32 | B33: Naveen P.; Sivakumar P. | C33: A deep convolution neural network for facial expression recognition | D33: Journal of Current Science and Technology | E33: 11 | G33: 2021 | H33: 10.14456/jcst.2021.40 | I33: https://www.scopus.com/inward/record.uri?eid=2-s2.0-85117325130&doi=10.14456%2fjcst.2021.40&partnerID=40&md5=b698397f86e160870ce3daeffd99d53d | J33: Article | K33: Scopus/WoS Journals | L33: ECE
A34: 33 | B34: Abirami S.K.; Keerthika J. | C34: Critical Evaluation of the Cloud-Based Design and Manufacturing | D34: Journal of Machine and Computing | E34: 1 | G34: 2021 | H34: 10.53759/7669/jmc202101019 | I34: https://www.scopus.com/inward/record.uri?eid=2-s2.0-85147532106&doi=10.53759%2f7669%2fjmc202101019&partnerID=40&md5=33847dd9cee4efd5862682e804a2b1fc | J34: Article | K34: SCI | L34: CSE
A35: 34 | B35: Sucharitha Y.; Raj P.A.C.; Karthik T.S.; Kapila D.; Mathiazhagan V.; Walia R. | C35: Implementing an effective and secure resource architecture for vlsi block encryption | D35: Journal of Nuclear Energy Science and Power Generation Technology | E35: 10 | G35: 2021 | I35: https://www.scopus.com/inward/record.uri?eid=2-s2.0-85118343937&partnerID=40&md5=98759389645dc4d88a4817aa86a51413 | J35: Article | K35: Scopus/WoS Journals | L35: ECE
A36: 35 | B36: Priyadharshini S.; Shanthi S. | C36: A Survey on Detecting Android Malware Using Machine Learning Technique | D36: 2021 7th International Conference on Advanced Computing and Communication Systems, ICACCS 2021 | G36: 2021 | H36: 10.1109/ICACCS51430.2021.9441712 | I36: https://www.scopus.com/inward/record.uri?eid=2-s2.0-85108027428&doi=10.1109%2fICACCS51430.2021.9441712&partnerID=40&md5=4b14fde7647b20ecaeeb543fd8744972 | J36: Conference paper | K36: Scopus/WoS Conference/Book Chapter/Others | L36: CSE
A37: 36 | B37: Saranya N.; Sakthi Samyuktha M.; Isaac S.; Subhanki B. | C37: Diagnosing Chronic Kidney Disease using KNN Algorithm | D37: 2021 7th International Conference on Advanced Computing and Communication Systems, ICACCS 2021 | G37: 2021 | H37: 10.1109/ICACCS51430.2021.9442039 | I37: https://www.scopus.com/inward/record.uri?eid=2-s2.0-85108022899&doi=10.1109%2fICACCS51430.2021.9442039&partnerID=40&md5=4b795bcf839902d3ce460f4e4e9e2870 | J37: Conference paper | K37: Scopus/WoS Conference/Book Chapter/Others | L37: CSE
A38: 37 | B38: Gayathri N.; Divagaran A.R.; Akhilesh C.D.; Aswiin V.M.; Charan N. | C38: IOT Based Smart Waste Management System | D38: 2021 7th International Conference on Advanced Computing and Communication Systems, ICACCS 2021 | G38: 2021 | H38: 10.1109/ICACCS51430.2021.9441819 | I38: https://www.scopus.com/inward/record.uri?eid=2-s2.0-85108024201&doi=10.1109%2fICACCS51430.2021.9441819&partnerID=40&md5=e1669d0e0fbe2c9de27e70cf7aab69cb | J38: Conference paper | K38: Scopus/WoS Conference/Book Chapter/Others | L38: CSE
A39: 38 | B39: Velmurugan S.; Shanthi G.; Raja L.; Nirmala S. | C39: Fully Automated Single Window Saline Fluid Flow Control and Automatic Container Changing System | D39: 2021 7th International Conference on Advanced Computing and Communication Systems, ICACCS 2021 | G39: 2021 | H39: 10.1109/ICACCS51430.2021.9441723 | I39: https://www.scopus.com/inward/record.uri?eid=2-s2.0-85108026228&doi=10.1109%2fICACCS51430.2021.9441723&partnerID=40&md5=48855fb5d9366e1217bae67876a69504 | J39: Conference paper | K39: Scopus/WoS Conference/Book Chapter/Others | L39: ECE
A40: 39 | B40: Sreemathy J.; Brindha R.; Selva Nagalakshmi M.; Suvekha N.; Karthick Ragul N.; Praveennandha M. | C40: Overview of ETL Tools and Talend-Data Integration | D40: 2021 7th International Conference on Advanced Computing and Communication Systems, ICACCS 2021 | G40: 2021 | H40: 10.1109/ICACCS51430.2021.9441984 | I40: https://www.scopus.com/inward/record.uri?eid=2-s2.0-85108029699&doi=10.1109%2fICACCS51430.2021.9441984&partnerID=40&md5=09193dde92d718a4bbec55419472a897 | J40: Conference paper | K40: Scopus/WoS Conference/Book Chapter/Others | L40: CSE
...

Sheet Name of the Faculty 2023
A1: S.No | B1: Name of the Faculty | C1: Deptartment | D1: Dept | E1: SCI - 2023 | F1: Scopus/WoS Journals - 2023 | G1: Scopus/WoS Conference/Book Chapter/Others - 2023 | H1: Student Publication | I1: Book | J1: Total | O1: Combined Department
A2: 1 | B2: Dr. Dinesh Kumar P | C2: AIDS | D2: AIDS | E2: =COUNTIFS('2024 -2025-2026'!$M:$M,B2,'2024 -2025-2026'!$K:$K,"SCI",'2024 -2025-2026'!$G:$G,"2023") -> 0 | F2: =COUNTIFS('2024 -2025-2026'!$M:$M,B2,'2024 -2025-2026'!$K:$K,"Scopus/WoS Journals",'2024 -2025-2026'!$G:$G,"2023") -> 0 | G2: =COUNTIFS('2024 -2025-2026'!$M:$M,B2,'2024 -2025-2026'!$K:$K,"Scopus/WoS Conference/Book Chapter/Others", '2024 -2025-2026'!$G:$G,"2023") -> 0 | H2: =COUNTIFS('2024 -2025-2026'!$M:$M,B2,'2024 -2025-2026'!$K:$K,"Student Publication",'2024 -2025-2026'!$G:$G,"2023") -> 0 | I2: =COUNTIFS('2024 -2025-2026'!$M:$M,B2,'2024 -2025-2026'!$K:$K,"Book",'2024 -2025-2026'!$G:$G,"2023") -> 0 | J2: =SUM(E2:H2) -> 0 | L2: SCI | M2: =SUM(E2:E1248) -> 189 | O2: AIDS
A3: 2 | B3: Dr. Geetha M P | C3: AIDS | D3: AIDS | E3: =COUNTIFS('2024 -2025-2026'!$M:$M,B3,'2024 -2025-2026'!$K:$K,"SCI",'2024 -2025-2026'!$G:$G,"2023") -> 0 | F3: =COUNTIFS('2024 -2025-2026'!$M:$M,B3,'2024 -2025-2026'!$K:$K,"Scopus/WoS Journals",'2024 -2025-2026'!$G:$G,"2023") -> 0 | G3: =COUNTIFS('2024 -2025-2026'!$M:$M,B3,'2024 -2025-2026'!$K:$K,"Scopus/WoS Conference/Book Chapter/Others", '2024 -2025-2026'!$G:$G,"2023") -> 0 | H3: =COUNTIFS('2024 -2025-2026'!$M:$M,B3,'2024 -2025-2026'!$K:$K,"Student Publication",'2024 -2025-2026'!$G:$G,"2023") -> 0 | I3: =COUNTIFS('2024 -2025-2026'!$M:$M,B3,'2024 -2025-2026'!$K:$K,"Book",'2024 -2025-2026'!$G:$G,"2023") -> 0 | J3: =SUM(E3:H3) -> 0 | L3: Scopus/WoS Journals | M3: =SUM(F:F) -> 10 | O3: AIML
A4: 3 | B4: Dr. Kanimozhi T | C4: AIDS | D4: AIDS | E4: =COUNTIFS('2024 -2025-2026'!$M:$M,B4,'2024 -2025-2026'!$K:$K,"SCI",'2024 -2025-2026'!$G:$G,"2023") -> 0 | F4: =COUNTIFS('2024 -2025-2026'!$M:$M,B4,'2024 -2025-2026'!$K:$K,"Scopus/WoS Journals",'2024 -2025-2026'!$G:$G,"2023") -> 0 | G4: =COUNTIFS('2024 -2025-2026'!$M:$M,B4,'2024 -2025-2026'!$K:$K,"Scopus/WoS Conference/Book Chapter/Others", '2024 -2025-2026'!$G:$G,"2023") -> 0 | H4: =COUNTIFS('2024 -2025-2026'!$M:$M,B4,'2024 -2025-2026'!$K:$K,"Student Publication",'2024 -2025-2026'!$G:$G,"2023") -> 0 | I4: =COUNTIFS('2024 -2025-2026'!$M:$M,B4,'2024 -2025-2026'!$K:$K,"Book",'2024 -2025-2026'!$G:$G,"2023") -> 0 | J4: =SUM(E4:H4) -> 0 | L4: Scopus/WoS Conference/Book Chapter/Others | M4: =SUM(G:G) -> 296 | O4: CCE
A5: 4 | B5: Dr. Lakshmi M | C5: AIDS | D5: AIDS | E5: =COUNTIFS('2024 -2025-2026'!$M:$M,B5,'2024 -2025-2026'!$K:$K,"SCI",'2024 -2025-2026'!$G:$G,"2023") -> 0 | F5: =COUNTIFS('2024 -2025-2026'!$M:$M,B5,'2024 -2025-2026'!$K:$K,"Scopus/WoS Journals",'2024 -2025-2026'!$G:$G,"2023") -> 0 | G5: =COUNTIFS('2024 -2025-2026'!$M:$M,B5,'2024 -2025-2026'!$K:$K,"Scopus/WoS Conference/Book Chapter/Others", '2024 -2025-2026'!$G:$G,"2023") -> 0 | H5: =COUNTIFS('2024 -2025-2026'!$M:$M,B5,'2024 -2025-2026'!$K:$K,"Student Publication",'2024 -2025-2026'!$G:$G,"2023") -> 0 | I5: =COUNTIFS('2024 -2025-2026'!$M:$M,B5,'2024 -2025-2026'!$K:$K,"Book",'2024 -2025-2026'!$G:$G,"2023") -> 0 | J5: =SUM(E5:H5) -> 0 | L5: Student Publication | M5: =SUM(H:H) -> 122 | O5: CSBS
A6: 5 | B6: Dr. Mohammed Mustafa M | C6: AIDS | D6: AIDS | E6: =COUNTIFS('2024 -2025-2026'!$M:$M,B6,'2024 -2025-2026'!$K:$K,"SCI",'2024 -2025-2026'!$G:$G,"2023") -> 0 | F6: =COUNTIFS('2024 -2025-2026'!$M:$M,B6,'2024 -2025-2026'!$K:$K,"Scopus/WoS Journals",'2024 -2025-2026'!$G:$G,"2023") -> 0 | G6: =COUNTIFS('2024 -2025-2026'!$M:$M,B6,'2024 -2025-2026'!$K:$K,"Scopus/WoS Conference/Book Chapter/Others", '2024 -2025-2026'!$G:$G,"2023") -> 0 | H6: =COUNTIFS('2024 -2025-2026'!$M:$M,B6,'2024 -2025-2026'!$K:$K,"Student Publication",'2024 -2025-2026'!$G:$G,"2023") -> 0 | I6: =COUNTIFS('2024 -2025-2026'!$M:$M,B6,'2024 -2025-2026'!$K:$K,"Book",'2024 -2025-2026'!$G:$G,"2023") -> 0 | J6: =SUM(E6:H6) -> 0 | L6: Book | M6: =SUM(I:I) -> 4 | O6: CSE
A7: 6 | B7: Dr. Nivaashini M | C7: AIDS | D7: AIDS | E7: =COUNTIFS('2024 -2025-2026'!$M:$M,B7,'2024 -2025-2026'!$K:$K,"SCI",'2024 -2025-2026'!$G:$G,"2023") -> 0 | F7: =COUNTIFS('2024 -2025-2026'!$M:$M,B7,'2024 -2025-2026'!$K:$K,"Scopus/WoS Journals",'2024 -2025-2026'!$G:$G,"2023") -> 0 | G7: =COUNTIFS('2024 -2025-2026'!$M:$M,B7,'2024 -2025-2026'!$K:$K,"Scopus/WoS Conference/Book Chapter/Others", '2024 -2025-2026'!$G:$G,"2023") -> 0 | H7: =COUNTIFS('2024 -2025-2026'!$M:$M,B7,'2024 -2025-2026'!$K:$K,"Student Publication",'2024 -2025-2026'!$G:$G,"2023") -> 0 | I7: =COUNTIFS('2024 -2025-2026'!$M:$M,B7,'2024 -2025-2026'!$K:$K,"Book",'2024 -2025-2026'!$G:$G,"2023") -> 0 | J7: =SUM(E7:H7) -> 0 | L7: Total | M7: =SUM(M2:M6) -> 621 | O7: ECE
A8: 7 | B8: Dr. Sathish Kumar G | C8: AIDS | D8: AIDS | E8: =COUNTIFS('2024 -2025-2026'!$M:$M,B8,'2024 -2025-2026'!$K:$K,"SCI",'2024 -2025-2026'!$G:$G,"2023") -> 1 | F8: =COUNTIFS('2024 -2025-2026'!$M:$M,B8,'2024 -2025-2026'!$K:$K,"Scopus/WoS Journals",'2024 -2025-2026'!$G:$G,"2023") -> 0 | G8: =COUNTIFS('2024 -2025-2026'!$M:$M,B8,'2024 -2025-2026'!$K:$K,"Scopus/WoS Conference/Book Chapter/Others", '2024 -2025-2026'!$G:$G,"2023") -> 1 | H8: =COUNTIFS('2024 -2025-2026'!$M:$M,B8,'2024 -2025-2026'!$K:$K,"Student Publication",'2024 -2025-2026'!$G:$G,"2023") -> 0 | I8: =COUNTIFS('2024 -2025-2026'!$M:$M,B8,'2024 -2025-2026'!$K:$K,"Book",'2024 -2025-2026'!$G:$G,"2023") -> 0 | J8: =SUM(E8:H8) -> 2 | O8: MECH
A9: 8 | B9: Dr. Thenmozhi M | C9: AIDS | D9: AIDS | E9: =COUNTIFS('2024 -2025-2026'!$M:$M,B9,'2024 -2025-2026'!$K:$K,"SCI",'2024 -2025-2026'!$G:$G,"2023") -> 0 | F9: =COUNTIFS('2024 -2025-2026'!$M:$M,B9,'2024 -2025-2026'!$K:$K,"Scopus/WoS Journals",'2024 -2025-2026'!$G:$G,"2023") -> 0 | G9: =COUNTIFS('2024 -2025-2026'!$M:$M,B9,'2024 -2025-2026'!$K:$K,"Scopus/WoS Conference/Book Chapter/Others", '2024 -2025-2026'!$G:$G,"2023") -> 1 | H9: =COUNTIFS('2024 -2025-2026'!$M:$M,B9,'2024 -2025-2026'!$K:$K,"Student Publication",'2024 -2025-2026'!$G:$G,"2023") -> 1 | I9: =COUNTIFS('2024 -2025-2026'!$M:$M,B9,'2024 -2025-2026'!$K:$K,"Book",'2024 -2025-2026'!$G:$G,"2023") -> 0 | J9: =SUM(E9:H9) -> 2 | O9: EEE
A10: 9 | B10: Dr. Vimal S | C10: AIDS | D10: AIDS | E10: =COUNTIFS('2024 -2025-2026'!$M:$M,B10,'2024 -2025-2026'!$K:$K,"SCI",'2024 -2025-2026'!$G:$G,"2023") -> 0 | F10: =COUNTIFS('2024 -2025-2026'!$M:$M,B10,'2024 -2025-2026'!$K:$K,"Scopus/WoS Journals",'2024 -2025-2026'!$G:$G,"2023") -> 0 | G10: =COUNTIFS('2024 -2025-2026'!$M:$M,B10,'2024 -2025-2026'!$K:$K,"Scopus/WoS Conference/Book Chapter/Others", '2024 -2025-2026'!$G:$G,"2023") -> 0 | H10: =COUNTIFS('2024 -2025-2026'!$M:$M,B10,'2024 -2025-2026'!$K:$K,"Student Publication",'2024 -2025-2026'!$G:$G,"2023") -> 0 | I10: =COUNTIFS('2024 -2025-2026'!$M:$M,B10,'2024 -2025-2026'!$K:$K,"Book",'2024 -2025-2026'!$G:$G,"2023") -> 0 | J10: =SUM(E10:H10) -> 0 | O10: IT
A11: 10 | B11: Mr. Sridharan S | C11: AIDS | D11: AIDS | E11: =COUNTIFS('2024 -2025-2026'!$M:$M,B11,'2024 -2025-2026'!$K:$K,"SCI",'2024 -2025-2026'!$G:$G,"2023") -> 0 | F11: =COUNTIFS('2024 -2025-2026'!$M:$M,B11,'2024 -2025-2026'!$K:$K,"Scopus/WoS Journals",'2024 -2025-2026'!$G:$G,"2023") -> 0 | G11: =COUNTIFS('2024 -2025-2026'!$M:$M,B11,'2024 -2025-2026'!$K:$K,"Scopus/WoS Conference/Book Chapter/Others", '2024 -2025-2026'!$G:$G,"2023") -> 0 | H11: =COUNTIFS('2024 -2025-2026'!$M:$M,B11,'2024 -2025-2026'!$K:$K,"Student Publication",'2024 -2025-2026'!$G:$G,"2023") -> 0 | I11: =COUNTIFS('2024 -2025-2026'!$M:$M,B11,'2024 -2025-2026'!$K:$K,"Book",'2024 -2025-2026'!$G:$G,"2023") -> 0 | J11: =SUM(E11:H11) -> 0 | O11: S&H (Eng)
A12: 11 | B12: Ms. Anitha E | C12: AIDS | D12: AIDS | E12: =COUNTIFS('2024 -2025-2026'!$M:$M,B12,'2024 -2025-2026'!$K:$K,"SCI",'2024 -2025-2026'!$G:$G,"2023") -> 0 | F12: =COUNTIFS('2024 -2025-2026'!$M:$M,B12,'2024 -2025-2026'!$K:$K,"Scopus/WoS Journals",'2024 -2025-2026'!$G:$G,"2023") -> 1 | G12: =COUNTIFS('2024 -2025-2026'!$M:$M,B12,'2024 -2025-2026'!$K:$K,"Scopus/WoS Conference/Book Chapter/Others", '2024 -2025-2026'!$G:$G,"2023") -> 0 | H12: =COUNTIFS('2024 -2025-2026'!$M:$M,B12,'2024 -2025-2026'!$K:$K,"Student Publication",'2024 -2025-2026'!$G:$G,"2023") -> 2 | I12: =COUNTIFS('2024 -2025-2026'!$M:$M,B12,'2024 -2025-2026'!$K:$K,"Book",'2024 -2025-2026'!$G:$G,"2023") -> 0 | J12: =SUM(E12:H12) -> 3 | O12: CSE, IT, CCE
A13: 12 | B13: Ms. Divyaprabha R | C13: AIDS | D13: AIDS | E13: =COUNTIFS('2024 -2025-2026'!$M:$M,B13,'2024 -2025-2026'!$K:$K,"SCI",'2024 -2025-2026'!$G:$G,"2023") -> 0 | F13: =COUNTIFS('2024 -2025-2026'!$M:$M,B13,'2024 -2025-2026'!$K:$K,"Scopus/WoS Journals",'2024 -2025-2026'!$G:$G,"2023") -> 0 | G13: =COUNTIFS('2024 -2025-2026'!$M:$M,B13,'2024 -2025-2026'!$K:$K,"Scopus/WoS Conference/Book Chapter/Others", '2024 -2025-2026'!$G:$G,"2023") -> 0 | H13: =COUNTIFS('2024 -2025-2026'!$M:$M,B13,'2024 -2025-2026'!$K:$K,"Student Publication",'2024 -2025-2026'!$G:$G,"2023") -> 0 | I13: =COUNTIFS('2024 -2025-2026'!$M:$M,B13,'2024 -2025-2026'!$K:$K,"Book",'2024 -2025-2026'!$G:$G,"2023") -> 0 | J13: =SUM(E13:H13) -> 0 | O13: MECH, S&H (Eng)
A14: 13 | B14: Ms. Esther Pushpam | C14: AIDS | D14: AIDS | E14: =COUNTIFS('2024 -2025-2026'!$M:$M,B14,'2024 -2025-2026'!$K:$K,"SCI",'2024 -2025-2026'!$G:$G,"2023") -> 0 | F14: =COUNTIFS('2024 -2025-2026'!$M:$M,B14,'2024 -2025-2026'!$K:$K,"Scopus/WoS Journals",'2024 -2025-2026'!$G:$G,"2023") -> 0 | G14: =COUNTIFS('2024 -2025-2026'!$M:$M,B14,'2024 -2025-2026'!$K:$K,"Scopus/WoS Conference/Book Chapter/Others", '2024 -2025-2026'!$G:$G,"2023") -> 0 | H14: =COUNTIFS('2024 -2025-2026'!$M:$M,B14,'2024 -2025-2026'!$K:$K,"Student Publication",'2024 -2025-2026'!$G:$G,"2023") -> 0 | I14: =COUNTIFS('2024 -2025-2026'!$M:$M,B14,'2024 -2025-2026'!$K:$K,"Book",'2024 -2025-2026'!$G:$G,"2023") -> 0 | J14: =SUM(E14:H14) -> 0 | O14: S&H (Che)
A15: 14 | B15: Ms. Geetha Rajakumari R | C15: AIDS | D15: AIDS | E15: =COUNTIFS('2024 -2025-2026'!$M:$M,B15,'2024 -2025-2026'!$K:$K,"SCI",'2024 -2025-2026'!$G:$G,"2023") -> 0 | F15: =COUNTIFS('2024 -2025-2026'!$M:$M,B15,'2024 -2025-2026'!$K:$K,"Scopus/WoS Journals",'2024 -2025-2026'!$G:$G,"2023") -> 0 | G15: =COUNTIFS('2024 -2025-2026'!$M:$M,B15,'2024 -2025-2026'!$K:$K,"Scopus/WoS Conference/Book Chapter/Others", '2024 -2025-2026'!$G:$G,"2023") -> 0 | H15: =COUNTIFS('2024 -2025-2026'!$M:$M,B15,'2024 -2025-2026'!$K:$K,"Student Publication",'2024 -2025-2026'!$G:$G,"2023") -> 0 | I15: =COUNTIFS('2024 -2025-2026'!$M:$M,B15,'2024 -2025-2026'!$K:$K,"Book",'2024 -2025-2026'!$G:$G,"2023") -> 0 | J15: =SUM(E15:H15) -> 0 | O15: S&H (Maths)
A16: 15 | B16: Ms. Gowri S | C16: AIDS | D16: AIDS | E16: =COUNTIFS('2024 -2025-2026'!$M:$M,B16,'2024 -2025-2026'!$K:$K,"SCI",'2024 -2025-2026'!$G:$G,"2023") -> 0 | F16: =COUNTIFS('2024 -2025-2026'!$M:$M,B16,'2024 -2025-2026'!$K:$K,"Scopus/WoS Journals",'2024 -2025-2026'!$G:$G,"2023") -> 0 | G16: =COUNTIFS('2024 -2025-2026'!$M:$M,B16,'2024 -2025-2026'!$K:$K,"Scopus/WoS Conference/Book Chapter/Others", '2024 -2025-2026'!$G:$G,"2023") -> 0 | H16: =COUNTIFS('2024 -2025-2026'!$M:$M,B16,'2024 -2025-2026'!$K:$K,"Student Publication",'2024 -2025-2026'!$G:$G,"2023") -> 0 | I16: =COUNTIFS('2024 -2025-2026'!$M:$M,B16,'2024 -2025-2026'!$K:$K,"Book",'2024 -2025-2026'!$G:$G,"2023") -> 0 | J16: =SUM(E16:H16) -> 0 | O16: S&H (Phy)
A17: 16 | B17: Ms. Parvathy K | C17: AIDS | D17: AIDS | E17: =COUNTIFS('2024 -2025-2026'!$M:$M,B17,'2024 -2025-2026'!$K:$K,"SCI",'2024 -2025-2026'!$G:$G,"2023") -> 0 | F17: =COUNTIFS('2024 -2025-2026'!$M:$M,B17,'2024 -2025-2026'!$K:$K,"Scopus/WoS Journals",'2024 -2025-2026'!$G:$G,"2023") -> 0 | G17: =COUNTIFS('2024 -2025-2026'!$M:$M,B17,'2024 -2025-2026'!$K:$K,"Scopus/WoS Conference/Book Chapter/Others", '2024 -2025-2026'!$G:$G,"2023") -> 2 | H17: =COUNTIFS('2024 -2025-2026'!$M:$M,B17,'2024 -2025-2026'!$K:$K,"Student Publication",'2024 -2025-2026'!$G:$G,"2023") -> 0 | I17: =COUNTIFS('2024 -2025-2026'!$M:$M,B17,'2024 -2025-2026'!$K:$K,"Book",'2024 -2025-2026'!$G:$G,"2023") -> 0 | J17: =SUM(E17:H17) -> 2 | O17: Student Publication AIDS
A18: 17 | B18: Ms. Rajalakshmi S | C18: AIDS | D18: AIDS | E18: =COUNTIFS('2024 -2025-2026'!$M:$M,B18,'2024 -2025-2026'!$K:$K,"SCI",'2024 -2025-2026'!$G:$G,"2023") -> 0 | F18: =COUNTIFS('2024 -2025-2026'!$M:$M,B18,'2024 -2025-2026'!$K:$K,"Scopus/WoS Journals",'2024 -2025-2026'!$G:$G,"2023") -> 0 | G18: =COUNTIFS('2024 -2025-2026'!$M:$M,B18,'2024 -2025-2026'!$K:$K,"Scopus/WoS Conference/Book Chapter/Others", '2024 -2025-2026'!$G:$G,"2023") -> 0 | H18: =COUNTIFS('2024 -2025-2026'!$M:$M,B18,'2024 -2025-2026'!$K:$K,"Student Publication",'2024 -2025-2026'!$G:$G,"2023") -> 0 | I18: =COUNTIFS('2024 -2025-2026'!$M:$M,B18,'2024 -2025-2026'!$K:$K,"Book",'2024 -2025-2026'!$G:$G,"2023") -> 0 | J18: =SUM(E18:H18) -> 0 | O18: Student Publication CCE
A19: 18 | B19: Ms. Sangavi V | C19: AIDS | D19: AIDS | E19: =COUNTIFS('2024 -2025-2026'!$M:$M,B19,'2024 -2025-2026'!$K:$K,"SCI",'2024 -2025-2026'!$G:$G,"2023") -> 0 | F19: =COUNTIFS('2024 -2025-2026'!$M:$M,B19,'2024 -2025-2026'!$K:$K,"Scopus/WoS Journals",'2024 -2025-2026'!$G:$G,"2023") -> 0 | G19: =COUNTIFS('2024 -2025-2026'!$M:$M,B19,'2024 -2025-2026'!$K:$K,"Scopus/WoS Conference/Book Chapter/Others", '2024 -2025-2026'!$G:$G,"2023") -> 0 | H19: =COUNTIFS('2024 -2025-2026'!$M:$M,B19,'2024 -2025-2026'!$K:$K,"Student Publication",'2024 -2025-2026'!$G:$G,"2023") -> 0 | I19: =COUNTIFS('2024 -2025-2026'!$M:$M,B19,'2024 -2025-2026'!$K:$K,"Book",'2024 -2025-2026'!$G:$G,"2023") -> 0 | J19: =SUM(E19:H19) -> 0 | O19: Student Publication CSBS
... A26: 108 | B26: Dr. Raja L | C26: AIDS | D26: AIDS | E26: =COUNTIFS('2024 -2025-2026'!$M:$M,B26,'2024 -2025-2026'!$K:$K,"SCI",'2024 -2025-2026'!$G:$G,"2023") -> 1 | F26: =COUNTIFS('2024 -2025-2026'!$M:$M,B26,'2024 -2025-2026'!$K:$K,"Scopus/WoS Journals",'2024 -2025-2026'!$G:$G,"2023") -> 0 | G26: =COUNTIFS('2024 -2025-2026'!$M:$M,B26,'2024 -2025-2026'!$K:$K,"Scopus/WoS Conference/Book Chapter/Others", '2024 -2025-2026'!$G:$G,"2023") -> 2 | H26: =COUNTIFS('2024 -2025-2026'!$M:$M,B26,'2024 -2025-2026'!$K:$K,"Student Publication",'2024 -2025-2026'!$G:$G,"2023") -> 3 | I26: =COUNTIFS('2024 -2025-2026'!$M:$M,B26,'2024 -2025-2026'!$K:$K,"Book",'2024 -2025-2026'!$G:$G,"2023") -> 0 | J26: =SUM(E26:H26) -> 6 | O26: Student Publication AIML
A27: 141 | B27: Dr. Suganyadevi K | C27: AIDS | D27: AIDS | E27: =COUNTIFS('2024 -2025-2026'!$M:$M,B27,'2024 -2025-2026'!$K:$K,"SCI",'2024 -2025-2026'!$G:$G,"2023") -> 1 | F27: =COUNTIFS('2024 -2025-2026'!$M:$M,B27,'2024 -2025-2026'!$K:$K,"Scopus/WoS Journals",'2024 -2025-2026'!$G:$G,"2023") -> 0 | G27: =COUNTIFS('2024 -2025-2026'!$M:$M,B27,'2024 -2025-2026'!$K:$K,"Scopus/WoS Conference/Book Chapter/Others", '2024 -2025-2026'!$G:$G,"2023") -> 1 | H27: =COUNTIFS('2024 -2025-2026'!$M:$M,B27,'2024 -2025-2026'!$K:$K,"Student Publication",'2024 -2025-2026'!$G:$G,"2023") -> 2 | I27: =COUNTIFS('2024 -2025-2026'!$M:$M,B27,'2024 -2025-2026'!$K:$K,"Book",'2024 -2025-2026'!$G:$G,"2023") -> 0 | J27: =SUM(E27:H27) -> 4
A28: 250 | B28: Others AIDS | C28: AIDS | D28: AIDS | E28: =COUNTIFS('2024 -2025-2026'!$M:$M,B28,'2024 -2025-2026'!$K:$K,"SCI",'2024 -2025-2026'!$G:$G,"2023") -> 0 | F28: =COUNTIFS('2024 -2025-2026'!$M:$M,B28,'2024 -2025-2026'!$K:$K,"Scopus/WoS Journals",'2024 -2025-2026'!$G:$G,"2023") -> 0 | G28: =COUNTIFS('2024 -2025-2026'!$M:$M,B28,'2024 -2025-2026'!$K:$K,"Scopus/WoS Conference/Book Chapter/Others", '2024 -2025-2026'!$G:$G,"2023") -> 0 | H28: =COUNTIFS('2024 -2025-2026'!$M:$M,B28,'2024 -2025-2026'!$K:$K,"Student Publication",'2024 -2025-2026'!$G:$G,"2023") -> 0 | I28: =COUNTIFS('2024 -2025-2026'!$M:$M,B28,'2024 -2025-2026'!$K:$K,"Book",'2024 -2025-2026'!$G:$G,"2023") -> 0 | J28: =SUM(E28:H28) -> 0
A29: 266 | B29: Mr. Divakar R | C29: AIDS | D29: AIDS | E29: =COUNTIFS('2024 -2025-2026'!$M:$M,B29,'2024 -2025-2026'!$K:$K,"SCI",'2024 -2025-2026'!$G:$G,"2023") -> 0 | F29: =COUNTIFS('2024 -2025-2026'!$M:$M,B29,'2024 -2025-2026'!$K:$K,"Scopus/WoS Journals",'2024 -2025-2026'!$G:$G,"2023") -> 0 | G29: =COUNTIFS('2024 -2025-2026'!$M:$M,B29,'2024 -2025-2026'!$K:$K,"Scopus/WoS Conference/Book Chapter/Others", '2024 -2025-2026'!$G:$G,"2023") -> 0 | H29: =COUNTIFS('2024 -2025-2026'!$M:$M,B29,'2024 -2025-2026'!$K:$K,"Student Publication",'2024 -2025-2026'!$G:$G,"2023") -> 0 | I29: =COUNTIFS('2024 -2025-2026'!$M:$M,B29,'2024 -2025-2026'!$K:$K,"Book",'2024 -2025-2026'!$G:$G,"2023") -> 0 | J29: =SUM(E29:H29) -> 0
A30: 267 | B30: Dr. Rajesh Kumar C | C30: AIDS | D30: AIDS | E30: =COUNTIFS('2024 -2025-2026'!$M:$M,B30,'2024 -2025-2026'!$K:$K,"SCI",'2024 -2025-2026'!$G:$G,"2023") -> 0 | F30: =COUNTIFS('2024 -2025-2026'!$M:$M,B30,'2024 -2025-2026'!$K:$K,"Scopus/WoS Journals",'2024 -2025-2026'!$G:$G,"2023") -> 0 | G30: =COUNTIFS('2024 -2025-2026'!$M:$M,B30,'2024 -2025-2026'!$K:$K,"Scopus/WoS Conference/Book Chapter/Others", '2024 -2025-2026'!$G:$G,"2023") -> 0 | H30: =COUNTIFS('2024 -2025-2026'!$M:$M,B30,'2024 -2025-2026'!$K:$K,"Student Publication",'2024 -2025-2026'!$G:$G,"2023") -> 0 | I30: =COUNTIFS('2024 -2025-2026'!$M:$M,B30,'2024 -2025-2026'!$K:$K,"Book",'2024 -2025-2026'!$G:$G,"2023") -> 0 | J30: =SUM(E30:H30) -> 0
A31: 268 | B31: Mr. Sam Peter S | C31: AIDS | D31: AIDS | E31: =COUNTIFS('2024 -2025-2026'!$M:$M,B31,'2024 -2025-2026'!$K:$K,"SCI",'2024 -2025-2026'!$G:$G,"2023") -> 0 | F31: =COUNTIFS('2024 -2025-2026'!$M:$M,B31,'2024 -2025-2026'!$K:$K,"Scopus/WoS Journals",'2024 -2025-2026'!$G:$G,"2023") -> 0 | G31: =COUNTIFS('2024 -2025-2026'!$M:$M,B31,'2024 -2025-2026'!$K:$K,"Scopus/WoS Conference/Book Chapter/Others", '2024 -2025-2026'!$G:$G,"2023") -> 0 | H31: =COUNTIFS('2024 -2025-2026'!$M:$M,B31,'2024 -2025-2026'!$K:$K,"Student Publication",'2024 -2025-2026'!$G:$G,"2023") -> 0 | I31: =COUNTIFS('2024 -2025-2026'!$M:$M,B31,'2024 -2025-2026'!$K:$K,"Book",'2024 -2025-2026'!$G:$G,"2023") -> 0 | J31: =SUM(E31:H31) -> 0
A32: 269 | B32: Ms. Chitra P | C32: AIDS | D32: AIDS | E32: =COUNTIFS('2024 -2025-2026'!$M:$M,B32,'2024 -2025-2026'!$K:$K,"SCI",'2024 -2025-2026'!$G:$G,"2023") -> 0 | F32: =COUNTIFS('2024 -2025-2026'!$M:$M,B32,'2024 -2025-2026'!$K:$K,"Scopus/WoS Journals",'2024 -2025-2026'!$G:$G,"2023") -> 0 | G32: =COUNTIFS('2024 -2025-2026'!$M:$M,B32,'2024 -2025-2026'!$K:$K,"Scopus/WoS Conference/Book Chapter/Others", '2024 -2025-2026'!$G:$G,"2023") -> 0 | H32: =COUNTIFS('2024 -2025-2026'!$M:$M,B32,'2024 -2025-2026'!$K:$K,"Student Publication",'2024 -2025-2026'!$G:$G,"2023") -> 0 | I32: =COUNTIFS('2024 -2025-2026'!$M:$M,B32,'2024 -2025-2026'!$K:$K,"Book",'2024 -2025-2026'!$G:$G,"2023") -> 0 | J32: =SUM(E32:H32) -> 0
A33: 270 | B33: Ms. Durga Devi G | C33: AIDS | D33: AIDS | E33: =COUNTIFS('2024 -2025-2026'!$M:$M,B33,'2024 -2025-2026'!$K:$K,"SCI",'2024 -2025-2026'!$G:$G,"2023") -> 0 | F33: =COUNTIFS('2024 -2025-2026'!$M:$M,B33,'2024 -2025-2026'!$K:$K,"Scopus/WoS Journals",'2024 -2025-2026'!$G:$G,"2023") -> 0 | G33: =COUNTIFS('2024 -2025-2026'!$M:$M,B33,'2024 -2025-2026'!$K:$K,"Scopus/WoS Conference/Book Chapter/Others", '2024 -2025-2026'!$G:$G,"2023") -> 0 | H33: =COUNTIFS('2024 -2025-2026'!$M:$M,B33,'2024 -2025-2026'!$K:$K,"Student Publication",'2024 -2025-2026'!$G:$G,"2023") -> 0 | I33: =COUNTIFS('2024 -2025-2026'!$M:$M,B33,'2024 -2025-2026'!$K:$K,"Book",'2024 -2025-2026'!$G:$G,"2023") -> 0 | J33: =SUM(E33:H33) -> 0
A34: 271 | B34: Ms. Hemamalini D | C34: AIDS | D34: AIDS | E34: =COUNTIFS('2024 -2025-2026'!$M:$M,B34,'2024 -2025-2026'!$K:$K,"SCI",'2024 -2025-2026'!$G:$G,"2023") -> 0 | F34: =COUNTIFS('2024 -2025-2026'!$M:$M,B34,'2024 -2025-2026'!$K:$K,"Scopus/WoS Journals",'2024 -2025-2026'!$G:$G,"2023") -> 0 | G34: =COUNTIFS('2024 -2025-2026'!$M:$M,B34,'2024 -2025-2026'!$K:$K,"Scopus/WoS Conference/Book Chapter/Others", '2024 -2025-2026'!$G:$G,"2023") -> 0 | H34: =COUNTIFS('2024 -2025-2026'!$M:$M,B34,'2024 -2025-2026'!$K:$K,"Student Publication",'2024 -2025-2026'!$G:$G,"2023") -> 0 | I34: =COUNTIFS('2024 -2025-2026'!$M:$M,B34,'2024 -2025-2026'!$K:$K,"Book",'2024 -2025-2026'!$G:$G,"2023") -> 0 | J34: =SUM(E34:H34) -> 0
A35: 272 | B35: Ms. Parimalam K | C35: AIDS | D35: AIDS | E35: =COUNTIFS('2024 -2025-2026'!$M:$M,B35,'2024 -2025-2026'!$K:$K,"SCI",'2024 -2025-2026'!$G:$G,"2023") -> 0 | F35: =COUNTIFS('2024 -2025-2026'!$M:$M,B35,'2024 -2025-2026'!$K:$K,"Scopus/WoS Journals",'2024 -2025-2026'!$G:$G,"2023") -> 0 | G35: =COUNTIFS('2024 -2025-2026'!$M:$M,B35,'2024 -2025-2026'!$K:$K,"Scopus/WoS Conference/Book Chapter/Others", '2024 -2025-2026'!$G:$G,"2023") -> 0 | H35: =COUNTIFS('2024 -2025-2026'!$M:$M,B35,'2024 -2025-2026'!$K:$K,"Student Publication",'2024 -2025-2026'!$G:$G,"2023") -> 0 | I35: =COUNTIFS('2024 -2025-2026'!$M:$M,B35,'2024 -2025-2026'!$K:$K,"Book",'2024 -2025-2026'!$G:$G,"2023") -> 0 | J35: =SUM(E35:H35) -> 0
A36: 273 | B36: Ms. Pooranam N | C36: AIDS | D36: AIDS | E36: =COUNTIFS('2024 -2025-2026'!$M:$M,B36,'2024 -2025-2026'!$K:$K,"SCI",'2024 -2025-2026'!$G:$G,"2023") -> 0 | F36: =COUNTIFS('2024 -2025-2026'!$M:$M,B36,'2024 -2025-2026'!$K:$K,"Scopus/WoS Journals",'2024 -2025-2026'!$G:$G,"2023") -> 0 | G36: =COUNTIFS('2024 -2025-2026'!$M:$M,B36,'2024 -2025-2026'!$K:$K,"Scopus/WoS Conference/Book Chapter/Others", '2024 -2025-2026'!$G:$G,"2023") -> 0 | H36: =COUNTIFS('2024 -2025-2026'!$M:$M,B36,'2024 -2025-2026'!$K:$K,"Student Publication",'2024 -2025-2026'!$G:$G,"2023") -> 0 | I36: =COUNTIFS('2024 -2025-2026'!$M:$M,B36,'2024 -2025-2026'!$K:$K,"Book",'2024 -2025-2026'!$G:$G,"2023") -> 0 | J36: =SUM(E36:H36) -> 0
A37: 274 | B37: Ms. Saranya C | C37: AIDS | D37: AIDS | E37: =COUNTIFS('2024 -2025-2026'!$M:$M,B37,'2024 -2025-2026'!$K:$K,"SCI",'2024 -2025-2026'!$G:$G,"2023") -> 0 | F37: =COUNTIFS('2024 -2025-2026'!$M:$M,B37,'2024 -2025-2026'!$K:$K,"Scopus/WoS Journals",'2024 -2025-2026'!$G:$G,"2023") -> 0 | G37: =COUNTIFS('2024 -2025-2026'!$M:$M,B37,'2024 -2025-2026'!$K:$K,"Scopus/WoS Conference/Book Chapter/Others", '2024 -2025-2026'!$G:$G,"2023") -> 0 | H37: =COUNTIFS('2024 -2025-2026'!$M:$M,B37,'2024 -2025-2026'!$K:$K,"Student Publication",'2024 -2025-2026'!$G:$G,"2023") -> 0 | I37: =COUNTIFS('2024 -2025-2026'!$M:$M,B37,'2024 -2025-2026'!$K:$K,"Book",'2024 -2025-2026'!$G:$G,"2023") -> 0 | J37: =SUM(E37:H37) -> 0
A38: 275 | B38: Dr. Shobana G | C38: AIDS | D38: AIDS | E38: =COUNTIFS('2024 -2025-2026'!$M:$M,B38,'2024 -2025-2026'!$K:$K,"SCI",'2024 -2025-2026'!$G:$G,"2023") -> 0 | F38: =COUNTIFS('2024 -2025-2026'!$M:$M,B38,'2024 -2025-2026'!$K:$K,"Scopus/WoS Journals",'2024 -2025-2026'!$G:$G,"2023") -> 0 | G38: =COUNTIFS('2024 -2025-2026'!$M:$M,B38,'2024 -2025-2026'!$K:$K,"Scopus/WoS Conference/Book Chapter/Others", '2024 -2025-2026'!$G:$G,"2023") -> 0 | H38: =COUNTIFS('2024 -2025-2026'!$M:$M,B38,'2024 -2025-2026'!$K:$K,"Student Publication",'2024 -2025-2026'!$G:$G,"2023") -> 0 | I38: =COUNTIFS('2024 -2025-2026'!$M:$M,B38,'2024 -2025-2026'!$K:$K,"Book",'2024 -2025-2026'!$G:$G,"2023") -> 0 | J38: =SUM(E38:H38) -> 0
A39: 276 | B39: Dr. Sivaramakrishnan A | C39: AIDS | D39: AIDS | E39: =COUNTIFS('2024 -2025-2026'!$M:$M,B39,'2024 -2025-2026'!$K:$K,"SCI",'2024 -2025-2026'!$G:$G,"2023") -> 0 | F39: =COUNTIFS('2024 -2025-2026'!$M:$M,B39,'2024 -2025-2026'!$K:$K,"Scopus/WoS Journals",'2024 -2025-2026'!$G:$G,"2023") -> 0 | G39: =COUNTIFS('2024 -2025-2026'!$M:$M,B39,'2024 -2025-2026'!$K:$K,"Scopus/WoS Conference/Book Chapter/Others", '2024 -2025-2026'!$G:$G,"2023") -> 0 | H39: =COUNTIFS('2024 -2025-2026'!$M:$M,B39,'2024 -2025-2026'!$K:$K,"Student Publication",'2024 -2025-2026'!$G:$G,"2023") -> 0 | I39: =COUNTIFS('2024 -2025-2026'!$M:$M,B39,'2024 -2025-2026'!$K:$K,"Book",'2024 -2025-2026'!$G:$G,"2023") -> 0 | J39: =SUM(E39:H39) -> 0
A40: 307 | E40: =COUNTIFS('2024 -2025-2026'!$M:$M,B40,'2024 -2025-2026'!$K:$K,"SCI",'2024 -2025-2026'!$G:$G,"2023") -> 0 | F40: =COUNTIFS('2024 -2025-2026'!$M:$M,B40,'2024 -2025-2026'!$K:$K,"Scopus/WoS Journals",'2024 -2025-2026'!$G:$G,"2023") -> 0 | G40: =COUNTIFS('2024 -2025-2026'!$M:$M,B40,'2024 -2025-2026'!$K:$K,"Scopus/WoS Conference/Book Chapter/Others", '2024 -2025-2026'!$G:$G,"2023") -> 0 | H40: =COUNTIFS('2024 -2025-2026'!$M:$M,B40,'2024 -2025-2026'!$K:$K,"Student Publication",'2024 -2025-2026'!$G:$G,"2023") -> 0 | I40: =COUNTIFS('2024 -2025-2026'!$M:$M,B40,'2024 -2025-2026'!$K:$K,"Book",'2024 -2025-2026'!$G:$G,"2023") -> 0 | J40: =SUM(E40:H40) -> 0
A41: 23 | B41: Dr. Karunakaran V | C41: AIML | D41: AIML | E41: =COUNTIFS('2024 -2025-2026'!$M:$M,B41,'2024 -2025-2026'!$K:$K,"SCI",'2024 -2025-2026'!$G:$G,"2023") -> 0 | F41: =COUNTIFS('2024 -2025-2026'!$M:$M,B41,'2024 -2025-2026'!$K:$K,"Scopus/WoS Journals",'2024 -2025-2026'!$G:$G,"2023") -> 0 | G41: =COUNTIFS('2024 -2025-2026'!$M:$M,B41,'2024 -2025-2026'!$K:$K,"Scopus/WoS Conference/Book Chapter/Others", '2024 -2025-2026'!$G:$G,"2023") -> 1 | H41: =COUNTIFS('2024 -2025-2026'!$M:$M,B41,'2024 -2025-2026'!$K:$K,"Student Publication",'2024 -2025-2026'!$G:$G,"2023") -> 0 | I41: =COUNTIFS('2024 -2025-2026'!$M:$M,B41,'2024 -2025-2026'!$K:$K,"Book",'2024 -2025-2026'!$G:$G,"2023") -> 0 | J41: =SUM(E41:H41) -> 1
A42: 24 | B42: Dr. Sumathi S | C42: AIML | D42: AIML | E42: =COUNTIFS('2024 -2025-2026'!$M:$M,B42,'2024 -2025-2026'!$K:$K,"SCI",'2024 -2025-2026'!$G:$G,"2023") -> 0 | F42: =COUNTIFS('2024 -2025-2026'!$M:$M,B42,'2024 -2025-2026'!$K:$K,"Scopus/WoS Journals",'2024 -2025-2026'!$G:$G,"2023") -> 0 | G42: =COUNTIFS('2024 -2025-2026'!$M:$M,B42,'2024 -2025-2026'!$K:$K,"Scopus/WoS Conference/Book Chapter/Others", '2024 -2025-2026'!$G:$G,"2023") -> 0 | H42: =COUNTIFS('2024 -2025-2026'!$M:$M,B42,'2024 -2025-2026'!$K:$K,"Student Publication",'2024 -2025-2026'!$G:$G,"2023") -> 2 | I42: =COUNTIFS('2024 -2025-2026'!$M:$M,B42,'2024 -2025-2026'!$K:$K,"Book",'2024 -2025-2026'!$G:$G,"2023") -> 0 | J42: =SUM(E42:H42) -> 2
A43: 25 | B43: Dr. Kathiresan K | C43: AIML | D43: AIML | E43: =COUNTIFS('2024 -2025-2026'!$M:$M,B43,'2024 -2025-2026'!$K:$K,"SCI",'2024 -2025-2026'!$G:$G,"2023") -> 0 | F43: =COUNTIFS('2024 -2025-2026'!$M:$M,B43,'2024 -2025-2026'!$K:$K,"Scopus/WoS Journals",'2024 -2025-2026'!$G:$G,"2023") -> 0 | G43: =COUNTIFS('2024 -2025-2026'!$M:$M,B43,'2024 -2025-2026'!$K:$K,"Scopus/WoS Conference/Book Chapter/Others", '2024 -2025-2026'!$G:$G,"2023") -> 0 | H43: =COUNTIFS('2024 -2025-2026'!$M:$M,B43,'2024 -2025-2026'!$K:$K,"Student Publication",'2024 -2025-2026'!$G:$G,"2023") -> 0 | I43: =COUNTIFS('2024 -2025-2026'!$M:$M,B43,'2024 -2025-2026'!$K:$K,"Book",'2024 -2025-2026'!$G:$G,"2023") -> 0 | J43: =SUM(E43:H43) -> 0
A44: 26 | B44: Ms. Preethi P | C44: AIML | D44: AIML | E44: =COUNTIFS('2024 -2025-2026'!$M:$M,B44,'2024 -2025-2026'!$K:$K,"SCI",'2024 -2025-2026'!$G:$G,"2023") -> 0 | F44: =COUNTIFS('2024 -2025-2026'!$M:$M,B44,'2024 -2025-2026'!$K:$K,"Scopus/WoS Journals",'2024 -2025-2026'!$G:$G,"2023") -> 0 | G44: =COUNTIFS('2024 -2025-2026'!$M:$M,B44,'2024 -2025-2026'!$K:$K,"Scopus/WoS Conference/Book Chapter/Others", '2024 -2025-2026'!$G:$G,"2023") -> 0 | H44: =COUNTIFS('2024 -2025-2026'!$M:$M,B44,'2024 -2025-2026'!$K:$K,"Student Publication",'2024 -2025-2026'!$G:$G,"2023") -> 0 | I44: =COUNTIFS('2024 -2025-2026'!$M:$M,B44,'2024 -2025-2026'!$K:$K,"Book",'2024 -2025-2026'!$G:$G,"2023") -> 0 | J44: =SUM(E44:H44) -> 0
A45: 27 | B45: Ms. Sindhuja S | C45: AIML | D45: AIML | E45: =COUNTIFS('2024 -2025-2026'!$M:$M,B45,'2024 -2025-2026'!$K:$K,"SCI",'2024 -2025-2026'!$G:$G,"2023") -> 0 | F45: =COUNTIFS('2024 -2025-2026'!$M:$M,B45,'2024 -2025-2026'!$K:$K,"Scopus/WoS Journals",'2024 -2025-2026'!$G:$G,"2023") -> 0 | G45: =COUNTIFS('2024 -2025-2026'!$M:$M,B45,'2024 -2025-2026'!$K:$K,"Scopus/WoS Conference/Book Chapter/Others", '2024 -2025-2026'!$G:$G,"2023") -> 0 | H45: =COUNTIFS('2024 -2025-2026'!$M:$M,B45,'2024 -2025-2026'!$K:$K,"Student Publication",'2024 -2025-2026'!$G:$G,"2023") -> 0 | I45: =COUNTIFS('2024 -2025-2026'!$M:$M,B45,'2024 -2025-2026'!$K:$K,"Book",'2024 -2025-2026'!$G:$G,"2023") -> 0 | J45: =SUM(E45:H45) -> 0
A46: 28 | B46: Ms. Kalaivani T | C46: AIML | D46: AIML | E46: =COUNTIFS('2024 -2025-2026'!$M:$M,B46,'2024 -2025-2026'!$K:$K,"SCI",'2024 -2025-2026'!$G:$G,"2023") -> 0 | F46: =COUNTIFS('2024 -2025-2026'!$M:$M,B46,'2024 -2025-2026'!$K:$K,"Scopus/WoS Journals",'2024 -2025-2026'!$G:$G,"2023") -> 0 | G46: =COUNTIFS('2024 -2025-2026'!$M:$M,B46,'2024 -2025-2026'!$K:$K,"Scopus/WoS Conference/Book Chapter/Others", '2024 -2025-2026'!$G:$G,"2023") -> 0 | H46: =COUNTIFS('2024 -2025-2026'!$M:$M,B46,'2024 -2025-2026'!$K:$K,"Student Publication",'2024 -2025-2026'!$G:$G,"2023") -> 0 | I46: =COUNTIFS('2024 -2025-2026'!$M:$M,B46,'2024 -2025-2026'!$K:$K,"Book",'2024 -2025-2026'!$G:$G,"2023") -> 0 | J46: =SUM(E46:H46) -> 0
...

Sheet Name of the Faculty 2024
A1: S.No | B1: Name of the Faculty | C1: Dept | D1: SCI - 2024 | E1: Scopus/WoS Journals - 2024 | F1: Scopus/WoS Conference/Book Chapter/Others - 2024 | G1: Student Publication | H1: Total | I1: TOTAL WITHOUT STUDENT pUBLICATION | M1: Combined Department
A2: 1 | B2: Dr. Dinesh Kumar P | C2: AIDS | D2: =COUNTIFS('2024 -2025-2026'!$M:$M,B2,'2024 -2025-2026'!$K:$K,"SCI",'2024 -2025-2026'!$G:$G,"2024") -> 0 | E2: =COUNTIFS('2024 -2025-2026'!$M:$M,B2,'2024 -2025-2026'!$K:$K,"Scopus/WoS Journals",'2024 -2025-2026'!$G:$G,"2024") -> 0 | F2: =COUNTIFS('2024 -2025-2026'!$M:$M,B2,'2024 -2025-2026'!$K:$K,"Scopus/WoS Conference/Book Chapter/Others", '2024 -2025-2026'!$G:$G,"2024") -> 1 | G2: =COUNTIFS('2024 -2025-2026'!$M:$M,B2,'2024 -2025-2026'!$K:$K,"Student Publication",'2024 -2025-2026'!$G:$G,"2024") -> 0 | H2: =SUM(D2:G2) -> 1 | I2: =SUM(D2:F2) -> 1 | J2: SCI | K2: =SUM(D2:D1248) -> 260 | M2: AIDS
A3: 2 | B3: Dr. Geetha M P | C3: AIDS | D3: =COUNTIFS('2024 -2025-2026'!$M:$M,B3,'2024 -2025-2026'!$K:$K,"SCI",'2024 -2025-2026'!$G:$G,"2024") -> 1 | E3: =COUNTIFS('2024 -2025-2026'!$M:$M,B3,'2024 -2025-2026'!$K:$K,"Scopus/WoS Journals",'2024 -2025-2026'!$G:$G,"2024") -> 0 | F3: =COUNTIFS('2024 -2025-2026'!$M:$M,B3,'2024 -2025-2026'!$K:$K,"Scopus/WoS Conference/Book Chapter/Others", '2024 -2025-2026'!$G:$G,"2024") -> 0 | G3: =COUNTIFS('2024 -2025-2026'!$M:$M,B3,'2024 -2025-2026'!$K:$K,"Student Publication",'2024 -2025-2026'!$G:$G,"2024") -> 3 | H3: =SUM(D3:G3) -> 4 | I3: =SUM(D3:F3) -> 1 | J3: Scopus/WoS Journals | K3: =SUM(E:E) -> 44 | M3: AIML
A4: 3 | B4: Dr. Kanimozhi T | C4: AIDS | D4: =COUNTIFS('2024 -2025-2026'!$M:$M,B4,'2024 -2025-2026'!$K:$K,"SCI",'2024 -2025-2026'!$G:$G,"2024") -> 1 | E4: =COUNTIFS('2024 -2025-2026'!$M:$M,B4,'2024 -2025-2026'!$K:$K,"Scopus/WoS Journals",'2024 -2025-2026'!$G:$G,"2024") -> 0 | F4: =COUNTIFS('2024 -2025-2026'!$M:$M,B4,'2024 -2025-2026'!$K:$K,"Scopus/WoS Conference/Book Chapter/Others", '2024 -2025-2026'!$G:$G,"2024") -> 3 | G4: =COUNTIFS('2024 -2025-2026'!$M:$M,B4,'2024 -2025-2026'!$K:$K,"Student Publication",'2024 -2025-2026'!$G:$G,"2024") -> 1 | H4: =SUM(D4:G4) -> 5 | I4: =SUM(D4:F4) -> 4 | J4: Scopus/WoS Conference/Book Chapter/Others | K4: =SUM(F:F) -> 407 | M4: CCE
A5: 4 | B5: Dr. Lakshmi M | C5: AIDS | D5: =COUNTIFS('2024 -2025-2026'!$M:$M,B5,'2024 -2025-2026'!$K:$K,"SCI",'2024 -2025-2026'!$G:$G,"2024") -> 0 | E5: =COUNTIFS('2024 -2025-2026'!$M:$M,B5,'2024 -2025-2026'!$K:$K,"Scopus/WoS Journals",'2024 -2025-2026'!$G:$G,"2024") -> 0 | F5: =COUNTIFS('2024 -2025-2026'!$M:$M,B5,'2024 -2025-2026'!$K:$K,"Scopus/WoS Conference/Book Chapter/Others", '2024 -2025-2026'!$G:$G,"2024") -> 0 | G5: =COUNTIFS('2024 -2025-2026'!$M:$M,B5,'2024 -2025-2026'!$K:$K,"Student Publication",'2024 -2025-2026'!$G:$G,"2024") -> 0 | H5: =SUM(D5:G5) -> 0 | I5: =SUM(D5:F5) -> 0 | J5: Student Publication | K5: =SUM(G:G) -> 251 | M5: CSBS
A6: 5 | B6: Dr. Mohammed Mustafa M | C6: AIDS | D6: =COUNTIFS('2024 -2025-2026'!$M:$M,B6,'2024 -2025-2026'!$K:$K,"SCI",'2024 -2025-2026'!$G:$G,"2024") -> 0 | E6: =COUNTIFS('2024 -2025-2026'!$M:$M,B6,'2024 -2025-2026'!$K:$K,"Scopus/WoS Journals",'2024 -2025-2026'!$G:$G,"2024") -> 0 | F6: =COUNTIFS('2024 -2025-2026'!$M:$M,B6,'2024 -2025-2026'!$K:$K,"Scopus/WoS Conference/Book Chapter/Others", '2024 -2025-2026'!$G:$G,"2024") -> 0 | G6: =COUNTIFS('2024 -2025-2026'!$M:$M,B6,'2024 -2025-2026'!$K:$K,"Student Publication",'2024 -2025-2026'!$G:$G,"2024") -> 1 | H6: =SUM(D6:G6) -> 1 | I6: =SUM(D6:F6) -> 0 | J6: Total | K6: =SUM(K2:K5) -> 962 | M6: CSE
A7: 6 | B7: Dr. Nivaashini M | C7: AIDS | D7: =COUNTIFS('2024 -2025-2026'!$M:$M,B7,'2024 -2025-2026'!$K:$K,"SCI",'2024 -2025-2026'!$G:$G,"2024") -> 1 | E7: =COUNTIFS('2024 -2025-2026'!$M:$M,B7,'2024 -2025-2026'!$K:$K,"Scopus/WoS Journals",'2024 -2025-2026'!$G:$G,"2024") -> 0 | F7: =COUNTIFS('2024 -2025-2026'!$M:$M,B7,'2024 -2025-2026'!$K:$K,"Scopus/WoS Conference/Book Chapter/Others", '2024 -2025-2026'!$G:$G,"2024") -> 5 | G7: =COUNTIFS('2024 -2025-2026'!$M:$M,B7,'2024 -2025-2026'!$K:$K,"Student Publication",'2024 -2025-2026'!$G:$G,"2024") -> 2 | H7: =SUM(D7:G7) -> 8 | I7: =SUM(D7:F7) -> 6 | M7: ECE
A8: 7 | B8: Dr. Sathish Kumar G | C8: AIDS | D8: =COUNTIFS('2024 -2025-2026'!$M:$M,B8,'2024 -2025-2026'!$K:$K,"SCI",'2024 -2025-2026'!$G:$G,"2024") -> 4 | E8: =COUNTIFS('2024 -2025-2026'!$M:$M,B8,'2024 -2025-2026'!$K:$K,"Scopus/WoS Journals",'2024 -2025-2026'!$G:$G,"2024") -> 0 | F8: =COUNTIFS('2024 -2025-2026'!$M:$M,B8,'2024 -2025-2026'!$K:$K,"Scopus/WoS Conference/Book Chapter/Others", '2024 -2025-2026'!$G:$G,"2024") -> 0 | G8: =COUNTIFS('2024 -2025-2026'!$M:$M,B8,'2024 -2025-2026'!$K:$K,"Student Publication",'2024 -2025-2026'!$G:$G,"2024") -> 1 | H8: =SUM(D8:G8) -> 5 | I8: =SUM(D8:F8) -> 4 | M8: MECH
A9: 8 | B9: Dr. Thenmozhi M | C9: AIDS | D9: =COUNTIFS('2024 -2025-2026'!$M:$M,B9,'2024 -2025-2026'!$K:$K,"SCI",'2024 -2025-2026'!$G:$G,"2024") -> 0 | E9: =COUNTIFS('2024 -2025-2026'!$M:$M,B9,'2024 -2025-2026'!$K:$K,"Scopus/WoS Journals",'2024 -2025-2026'!$G:$G,"2024") -> 0 | F9: =COUNTIFS('2024 -2025-2026'!$M:$M,B9,'2024 -2025-2026'!$K:$K,"Scopus/WoS Conference/Book Chapter/Others", '2024 -2025-2026'!$G:$G,"2024") -> 4 | G9: =COUNTIFS('2024 -2025-2026'!$M:$M,B9,'2024 -2025-2026'!$K:$K,"Student Publication",'2024 -2025-2026'!$G:$G,"2024") -> 5 | H9: =SUM(D9:G9) -> 9 | I9: =SUM(D9:F9) -> 4 | M9: EEE
A10: 9 | B10: Dr. Vimal S | C10: AIDS | D10: =COUNTIFS('2024 -2025-2026'!$M:$M,B10,'2024 -2025-2026'!$K:$K,"SCI",'2024 -2025-2026'!$G:$G,"2024") -> 0 | E10: =COUNTIFS('2024 -2025-2026'!$M:$M,B10,'2024 -2025-2026'!$K:$K,"Scopus/WoS Journals",'2024 -2025-2026'!$G:$G,"2024") -> 0 | F10: =COUNTIFS('2024 -2025-2026'!$M:$M,B10,'2024 -2025-2026'!$K:$K,"Scopus/WoS Conference/Book Chapter/Others", '2024 -2025-2026'!$G:$G,"2024") -> 0 | G10: =COUNTIFS('2024 -2025-2026'!$M:$M,B10,'2024 -2025-2026'!$K:$K,"Student Publication",'2024 -2025-2026'!$G:$G,"2024") -> 0 | H10: =SUM(D10:G10) -> 0 | I10: =SUM(D10:F10) -> 0 | M10: IT
A11: 10 | B11: Mr. Sridharan S | C11: AIDS | D11: =COUNTIFS('2024 -2025-2026'!$M:$M,B11,'2024 -2025-2026'!$K:$K,"SCI",'2024 -2025-2026'!$G:$G,"2024") -> 0 | E11: =COUNTIFS('2024 -2025-2026'!$M:$M,B11,'2024 -2025-2026'!$K:$K,"Scopus/WoS Journals",'2024 -2025-2026'!$G:$G,"2024") -> 0 | F11: =COUNTIFS('2024 -2025-2026'!$M:$M,B11,'2024 -2025-2026'!$K:$K,"Scopus/WoS Conference/Book Chapter/Others", '2024 -2025-2026'!$G:$G,"2024") -> 0 | G11: =COUNTIFS('2024 -2025-2026'!$M:$M,B11,'2024 -2025-2026'!$K:$K,"Student Publication",'2024 -2025-2026'!$G:$G,"2024") -> 0 | H11: =SUM(D11:G11) -> 0 | I11: =SUM(D11:F11) -> 0 | M11: S&H (Eng)
A12: 11 | B12: Ms. Anitha E | C12: AIDS | D12: =COUNTIFS('2024 -2025-2026'!$M:$M,B12,'2024 -2025-2026'!$K:$K,"SCI",'2024 -2025-2026'!$G:$G,"2024") -> 0 | E12: =COUNTIFS('2024 -2025-2026'!$M:$M,B12,'2024 -2025-2026'!$K:$K,"Scopus/WoS Journals",'2024 -2025-2026'!$G:$G,"2024") -> 0 | F12: =COUNTIFS('2024 -2025-2026'!$M:$M,B12,'2024 -2025-2026'!$K:$K,"Scopus/WoS Conference/Book Chapter/Others", '2024 -2025-2026'!$G:$G,"2024") -> 0 | G12: =COUNTIFS('2024 -2025-2026'!$M:$M,B12,'2024 -2025-2026'!$K:$K,"Student Publication",'2024 -2025-2026'!$G:$G,"2024") -> 0 | H12: =SUM(D12:G12) -> 0 | I12: =SUM(D12:F12) -> 0 | M12: CSE, IT, CCE
A13: 12 | B13: Ms. Divyaprabha R | C13: AIDS | D13: =COUNTIFS('2024 -2025-2026'!$M:$M,B13,'2024 -2025-2026'!$K:$K,"SCI",'2024 -2025-2026'!$G:$G,"2024") -> 0 | E13: =COUNTIFS('2024 -2025-2026'!$M:$M,B13,'2024 -2025-2026'!$K:$K,"Scopus/WoS Journals",'2024 -2025-2026'!$G:$G,"2024") -> 0 | F13: =COUNTIFS('2024 -2025-2026'!$M:$M,B13,'2024 -2025-2026'!$K:$K,"Scopus/WoS Conference/Book Chapter/Others", '2024 -2025-2026'!$G:$G,"2024") -> 0 | G13: =COUNTIFS('2024 -2025-2026'!$M:$M,B13,'2024 -2025-2026'!$K:$K,"Student Publication",'2024 -2025-2026'!$G:$G,"2024") -> 0 | H13: =SUM(D13:G13) -> 0 | I13: =SUM(D13:F13) -> 0 | M13: MECH, S&H (Eng)
A14: 13 | B14: Ms. Esther Pushpam | C14: AIDS | D14: =COUNTIFS('2024 -2025-2026'!$M:$M,B14,'2024 -2025-2026'!$K:$K,"SCI",'2024 -2025-2026'!$G:$G,"2024") -> 0 | E14: =COUNTIFS('2024 -2025-2026'!$M:$M,B14,'2024 -2025-2026'!$K:$K,"Scopus/WoS Journals",'2024 -2025-2026'!$G:$G,"2024") -> 0 | F14: =COUNTIFS('2024 -2025-2026'!$M:$M,B14,'2024 -2025-2026'!$K:$K,"Scopus/WoS Conference/Book Chapter/Others", '2024 -2025-2026'!$G:$G,"2024") -> 0 | G14: =COUNTIFS('2024 -2025-2026'!$M:$M,B14,'2024 -2025-2026'!$K:$K,"Student Publication",'2024 -2025-2026'!$G:$G,"2024") -> 0 | H14: =SUM(D14:G14) -> 0 | I14: =SUM(D14:F14) -> 0 | M14: S&H (Che)
A15: 14 | B15: Ms. Geetha Rajakumari R | C15: AIDS | D15: =COUNTIFS('2024 -2025-2026'!$M:$M,B15,'2024 -2025-2026'!$K:$K,"SCI",'2024 -2025-2026'!$G:$G,"2024") -> 0 | E15: =COUNTIFS('2024 -2025-2026'!$M:$M,B15,'2024 -2025-2026'!$K:$K,"Scopus/WoS Journals",'2024 -2025-2026'!$G:$G,"2024") -> 0 | F15: =COUNTIFS('2024 -2025-2026'!$M:$M,B15,'2024 -2025-2026'!$K:$K,"Scopus/WoS Conference/Book Chapter/Others", '2024 -2025-2026'!$G:$G,"2024") -> 2 | G15: =COUNTIFS('2024 -2025-2026'!$M:$M,B15,'2024 -2025-2026'!$K:$K,"Student Publication",'2024 -2025-2026'!$G:$G,"2024") -> 1 | H15: =SUM(D15:G15) -> 3 | I15: =SUM(D15:F15) -> 2 | M15: S&H (Maths)
A16: 15 | B16: Ms. Gowri S | C16: AIDS | D16: =COUNTIFS('2024 -2025-2026'!$M:$M,B16,'2024 -2025-2026'!$K:$K,"SCI",'2024 -2025-2026'!$G:$G,"2024") -> 0 | E16: =COUNTIFS('2024 -2025-2026'!$M:$M,B16,'2024 -2025-2026'!$K:$K,"Scopus/WoS Journals",'2024 -2025-2026'!$G:$G,"2024") -> 0 | F16: =COUNTIFS('2024 -2025-2026'!$M:$M,B16,'2024 -2025-2026'!$K:$K,"Scopus/WoS Conference/Book Chapter/Others", '2024 -2025-2026'!$G:$G,"2024") -> 0 | G16: =COUNTIFS('2024 -2025-2026'!$M:$M,B16,'2024 -2025-2026'!$K:$K,"Student Publication",'2024 -2025-2026'!$G:$G,"2024") -> 0 | H16: =SUM(D16:G16) -> 0 | I16: =SUM(D16:F16) -> 0 | M16: S&H (Phy)
A17: 16 | B17: Ms. Parvathy K | C17: AIDS | D17: =COUNTIFS('2024 -2025-2026'!$M:$M,B17,'2024 -2025-2026'!$K:$K,"SCI",'2024 -2025-2026'!$G:$G,"2024") -> 0 | E17: =COUNTIFS('2024 -2025-2026'!$M:$M,B17,'2024 -2025-2026'!$K:$K,"Scopus/WoS Journals",'2024 -2025-2026'!$G:$G,"2024") -> 0 | F17: =COUNTIFS('2024 -2025-2026'!$M:$M,B17,'2024 -2025-2026'!$K:$K,"Scopus/WoS Conference/Book Chapter/Others", '2024 -2025-2026'!$G:$G,"2024") -> 1 | G17: =COUNTIFS('2024 -2025-2026'!$M:$M,B17,'2024 -2025-2026'!$K:$K,"Student Publication",'2024 -2025-2026'!$G:$G,"2024") -> 0 | H17: =SUM(D17:G17) -> 1 | I17: =SUM(D17:F17) -> 1 | M17: Student Publication AIDS
A18: 17 | B18: Ms. Rajalakshmi S | C18: AIDS | D18: =COUNTIFS('2024 -2025-2026'!$M:$M,B18,'2024 -2025-2026'!$K:$K,"SCI",'2024 -2025-2026'!$G:$G,"2024") -> 0 | E18: =COUNTIFS('2024 -2025-2026'!$M:$M,B18,'2024 -2025-2026'!$K:$K,"Scopus/WoS Journals",'2024 -2025-2026'!$G:$G,"2024") -> 0 | F18: =COUNTIFS('2024 -2025-2026'!$M:$M,B18,'2024 -2025-2026'!$K:$K,"Scopus/WoS Conference/Book Chapter/Others", '2024 -2025-2026'!$G:$G,"2024") -> 0 | G18: =COUNTIFS('2024 -2025-2026'!$M:$M,B18,'2024 -2025-2026'!$K:$K,"Student Publication",'2024 -2025-2026'!$G:$G,"2024") -> 0 | H18: =SUM(D18:G18) -> 0 | I18: =SUM(D18:F18) -> 0 | M18: Student Publication CCE
