Workbook

Sheet Required Columns - 2026
A1: Name of the Faculty | B1: Dept | C1: Target SCI - 2026 | D1: Target Scopus/WoS Journals - 2026 | E1: Target Scopus/WoS Conference/Book Chapter/Others - 2026 | F1: Designation in 2026 | G1: Type | H1: Student Publication Target | I1: Utility Patent Target | J1: Design Patent Target | K1: Copyright Target | L1: Funding Target | M1: Consultancy Target | N1: Design Patent
A2: Dr. Raja L | B2: AIDS | C2: 2 | D2: 2 | E2: 1 | F2: Prof. | G2: Doctorate | H2: 2 | I2: 1 | J2: 1 | K2: 0 | L2: 500000 | M2: 100000 | N2: =VLOOKUP(B2,Working!$B$2:$R$2208,17,0)
A3: Dr. Mohaideen Abdul Kadhar K | B3: AIDS | C3: 2 | D3: 2 | E3: 1 | F3: Prof. | G3: Doctorate | H3: 2 | I3: 1 | J3: 0 | K3: 0 | L3: 500000 | M3: 100000 | N3: =VLOOKUP(B3,Working!$B$2:$R$2208,17,0)
A4: Dr. Sheeba Rani Gnanamalar S | B4: AIDS | C4: 2 | D4: 2 | E4: 1 | F4: Prof. | G4: Doctorate | H4: 2 | I4: 0 | J4: 0 | K4: 0 | L4: 500000 | M4: 100000 | N4: =VLOOKUP(B4,Working!$B$2:$R$2208,17,0)
A5: Dr. Vivek C | B5: CCE | C5: 2 | D5: 2 | E5: 1 | F5: Prof. | G5: Doctorate | H5: 2 | I5: 2 | J5: 0 | K5: 0 | L5: 500000 | M5: 100000 | N5: =VLOOKUP(B5,Working!$B$2:$R$2208,17,0)
A6: Dr. Deepa R | B6: CCE | C6: 2 | D6: 2 | E6: 1 | F6: Prof. | G6: Doctorate | H6: 2 | I6: 1 | J6: 0 | K6: 0 | L6: 500000 | M6: 100000 | N6: =VLOOKUP(B6,Working!$B$2:$R$2208,17,0)
A7: Dr. Rajarajeswari P L | B7: CSBS | C7: 2 | D7: 2 | E7: 1 | F7: Prof. | G7: Doctorate | H7: 2 | I7: 2 | J7: 1 | K7: 0 | L7: 500000 | M7: 100000 | N7: =VLOOKUP(B7,Working!$B$2:$R$2208,17,0)
A8: Dr. Subha R | B8: CSE | C8: 2 | D8: 2 | E8: 1 | F8: Prof. | G8: Doctorate | H8: 2 | I8: 1 | J8: 0 | K8: 0 | L8: 500000 | M8: 100000 | N8: =VLOOKUP(B8,Working!$B$2:$R$2208,17,0)
A9: Dr. Akshaya V S | B9: CSE | C9: 2 | D9: 2 | E9: 1 | F9: Prof. | G9: Doctorate | H9: 2 | I9: 2 | J9: 0 | K9: 0 | L9: 500000 | M9: 100000 | N9: =VLOOKUP(B9,Working!$B$2:$R$2208,17,0)
A10: Dr. Anandakumar H | B10: CSE | C10: 3 | D10: 2 | E10: 5 | F10: Prof. | G10: Doctorate | H10: 0 | I10: 3 | J10: 1 | K10: 0 | L10: 500000 | M10: 100000 | N10: =VLOOKUP(B10,Working!$B$2:$R$2208,17,0)
A11: Dr. Shanmuga Sundaram N | B11: ECE | C11: 2 | D11: 2 | E11: 1 | F11: Prof. | G11: Doctorate | H11: 2 | I11: 2 | J11: 0 | K11: 0 | L11: 500000 | M11: 100000 | N11: =VLOOKUP(B11,Working!$B$2:$R$2208,17,0)
A12: Dr. Vijeyakumar K N | B12: ECE | C12: 2 | D12: 2 | E12: 1 | F12: Prof. | G12: Doctorate | H12: 2 | I12: 2 | J12: 0 | K12: 0 | L12: 500000 | M12: 100000 | N12: =VLOOKUP(B12,Working!$B$2:$R$2208,17,0)
A13: Dr. Kumareshan N | B13: ECE | C13: 2 | D13: 2 | E13: 1 | F13: Prof. | G13: Doctorate | H13: 2 | I13: 2 | J13: 0 | K13: 0 | L13: 500000 | M13: 100000 | N13: =VLOOKUP(B13,Working!$B$2:$R$2208,17,0)
... A232: Ms. Akiladevi N | B232: S & H (Maths) | C232: 0 | D232: 1 | E232: 2 | F232: AP | G232: Doing Ph.D - Others | H232: 0 | I232: 1 | J232: 0 | K232: 0 | L232: 100000 | M232: 40000 | N232: =VLOOKUP(B232,Working!$B$2:$R$2208,17,0)
A233: Dr. Lakshmanan M (T) | C233: 0 | D233: 0 | E233: 0 | F233: #N/A | G233: #N/A | H233: 0 | I233: 0 | J233: 0 | K233: 0 | L233: 0 | M233: 0 | N233: =VLOOKUP(B233,Working!$B$2:$R$2208,17,0)
A234: Dr. Mohaideen Abdul Kadhar K (T) | C234: 0 | D234: 0 | E234: 0 | F234: #N/A | G234: #N/A | H234: 0 | I234: 0 | J234: 0 | K234: 0 | L234: 0 | M234: 0 | N234: =VLOOKUP(B234,Working!$B$2:$R$2208,17,0)
A235: Dr. Raja L (T) | C235: 0 | D235: 0 | E235: 0 | F235: #N/A | G235: #N/A | H235: 0 | I235: 0 | J235: 0 | K235: 0 | L235: 0 | M235: 0 | N235: =VLOOKUP(B235,Working!$B$2:$R$2208,17,0)
A236: Dr. Sheeba Rani Gnanamalar S (T) | C236: 0 | D236: 0 | E236: 0 | F236: #N/A | G236: #N/A | H236: 0 | I236: 0 | J236: 0 | K236: 0 | L236: 0 | M236: 0 | N236: =VLOOKUP(B236,Working!$B$2:$R$2208,17,0)
A237: Ms. Sugunavathy S | B237: RS | C237: 0 | D237: 2 | E237: 3 | F237: Research Scholar | G237: Research Scholar | H237: 0 | I237: 0 | J237: 0 | K237: 0 | L237: 0 | M237: 0 | N237: =VLOOKUP(B237,Working!$B$2:$R$2208,17,0)
A238: Mr. Boopathi B | B238: RS | C238: 0 | D238: 2 | E238: 3 | F238: Research Scholar | G238: Research Scholar | H238: 0 | I238: 0 | J238: 0 | K238: 0 | L238: 0 | M238: 0 | N238: =VLOOKUP(B238,Working!$B$2:$R$2208,17,0)
A239: Ms. Divya T | B239: RS | C239: 0 | D239: 2 | E239: 3 | F239: Research Scholar | G239: Research Scholar | H239: 0 | I239: 0 | J239: 0 | K239: 0 | L239: 0 | M239: 0 | N239: =VLOOKUP(B239,Working!$B$2:$R$2208,17,0)
A240: Mr. Neelraj E | B240: RS | C240: 0 | D240: 2 | E240: 3 | F240: Research Scholar | G240: Research Scholar | H240: 0 | I240: 0 | J240: 0 | K240: 0 | L240: 0 | M240: 0 | N240: =VLOOKUP(B240,Working!$B$2:$R$2208,17,0)
A241: Ms. Saranya S | B241: RS | C241: 0 | D241: 2 | E241: 3 | F241: Research Scholar | G241: Research Scholar | H241: 0 | I241: 0 | J241: 0 | K241: 0 | L241: 0 | M241: 0 | N241: =VLOOKUP(B241,Working!$B$2:$R$2208,17,0)
A242: Mr. Manoj Kumar C | B242: RS | C242: 0 | D242: 2 | E242: 3 | F242: Research Scholar | G242: Research Scholar | H242: 0 | I242: 0 | J242: 0 | K242: 0 | L242: 0 | M242: 0 | N242: =VLOOKUP(B242,Working!$B$2:$R$2208,17,0)
A243: Dr. Lakshmanan M | B243: AIDS | C243: 0 | D243: 0 | E243: 0 | F243: Prof. | G243: Doctorate | H243: 0 | I243: 0 | J243: 0 | K243: 0 | L243: 0 | M243: 0 | N243: =VLOOKUP(B243,Working!$B$2:$R$2208,17,0)
A244: Dr. Sudha Mohanram | B244: EEE | C244: 0 | D244: 0 | E244: 0 | F244: Prof. | G244: Doctorate | H244: 0 | I244: 0 | J244: 0 | K244: 0 | L244: 0 | M244: 0 | N244: =VLOOKUP(B244,Working!$B$2:$R$2208,17,0)
A245: Dr. Chandrasekaran V | B245: EEE | C245: 0 | D245: 0 | E245: 0 | F245: Prof. | G245: Doctorate | H245: 0 | I245: 0 | J245: 0 | K245: 0 | L245: 0 | M245: 0 | N245: =VLOOKUP(B245,Working!$B$2:$R$2208,17,0)
A246: Dr. Karuppusami G | B246: MECH | C246: 0 | D246: 0 | E246: 0 | F246: Prof. | G246: Doctorate | H246: 0 | I246: 0 | J246: 0 | K246: 0 | L246: 0 | M246: 0 | N246: =VLOOKUP(B246,Working!$B$2:$R$2208,17,0)
A247: Mr.Alexander Jesus Gene | B247: AIDS | C247: 0 | D247: 0 | E247: 1 | F247: POP | G247: Not Registered | H247: 0 | I247: 0 | J247: 0 | K247: 0 | L247: 0 | M247: 0 | N247: =VLOOKUP(B247,Working!$B$2:$R$2208,17,0)
A248: Ms. Uma S V | B248: AIDS | C248: 0 | D248: 0 | E248: 1 | F248: POP | G248: Not Registered | H248: 0 | I248: 0 | J248: 0 | K248: 0 | L248: 0 | M248: 0 | N248: =VLOOKUP(B248,Working!$B$2:$R$2208,17,0)
... A321: Ms. Suruthi Krishna T | B321: ECE | C321: 0 | D321: 2 | E321: 3 | F321: AP | G321: Not Registered | H321: 0 | I321: 3 | J321: 0 | K321: 0 | L321: 0 | M321: 0 | N321: =VLOOKUP(B321,Working!$B$2:$R$2208,17,0)
A322: Dr. Vignesh A | B322: ECE | C322: 0 | D322: 1 | E322: 1 | F322: AP | H322: 0 | I322: 2 | J322: 0 | K322: 0 | L322: 0 | M322: 0 | N322: =VLOOKUP(B322,Working!$B$2:$R$2208,17,0)
A323: Dr. Santhiya P | B323: RF - S & H (Chemistry) | C323: 0 | D323: 2 | E323: 3 | F323: AP | H323: 0 | I323: 3 | J323: 0 | K323: 0 | L323: 0 | M323: 0 | N323: =VLOOKUP(B323,Working!$B$2:$R$2208,17,0)
A324: Others CSE (CYS) | B324: Cyber Security | C324: 0 | D324: 1 | E324: 1 | F324: AP | G324: Not Registered | H324: 0 | I324: 0 | J324: 0 | K324: 0 | L324: 0 | M324: 0 | N324: 0
A325: Mr. Mohanraj A | C325: 0 | D325: 2 | E325: 3 | F325: AP | H325: 0 | I325: 3 | J325: 0 | K325: 0 | L325: 0 | M325: 0
A326: Ms. Niranjani V | C326: 0 | D326: 2 | E326: 3 | F326: AP | H326: 0 | I326: 3 | J326: 0 | K326: 0 | L326: 0 | M326: 0
A327: Ms. Saranya N | C327: 0 | D327: 2 | E327: 3 | F327: AP | H327: 0 | I327: 3 | J327: 0 | K327: 0 | L327: 0 | M327: 0
A328: Ms. Sivaranjani K | C328: 0 | D328: 2 | E328: 3 | F328: AP | H328: 0 | I328: 3 | J328: 0 | K328: 0 | L328: 0 | M328: 0
A329: Visiting Professor | H329: 0 | I329: 3 | J329: 0 | K329: 0 | L329: 0 | M329: 0
A330: Dr. Ananthanarayanan | B330: AIDS | C330: 0 | D330: 1 | E330: 1 | F330: Prof. | H330: 0 | I330: 1 | J330: 0 | K330: 0 | L330: 0 | M330: 0
...
